Workbook

Sheet Mẫu T
A2: STT | B2: Ngày/tháng | C2: Ngân sách cấp | D2: Tổng đã tiêu | E2: Số đơn | F2: Doanh số | G2: Tỷ lệ CP
C3: =+SUM(C4:C34) -> 0 | D3: =SUM(D4:D34) -> 0 | E3: =SUM(E4:E34) -> 0 | F3: =SUM(F4:F36) -> 0 | G3: =IFERROR(D3/F3,0) -> 0
A4: 1 | B4: 46204 | G4: =IFERROR(D4/F4,0) -> 0
A5: 2 | B5: 46205 | G5: =IFERROR(D5/F5,0) -> 0
A6: 3 | B6: 46206 | G6: =IFERROR(D6/F6,0) -> 0
A7: 4 | B7: 46207 | G7: =IFERROR(D7/F7,0) -> 0
A8: 5 | B8: 46208 | G8: =IFERROR(D8/F8,0) -> 0
A9: 6 | B9: 46209 | G9: =IFERROR(D9/F9,0) -> 0
A10: 7 | B10: 46210 | G10: =IFERROR(D10/F10,0) -> 0
A11: 8 | B11: 46211 | G11: =IFERROR(D11/F11,0) -> 0
A12: 9 | B12: 46212 | G12: =IFERROR(D12/F12,0) -> 0
A13: 10 | B13: 46213 | G13: =IFERROR(D13/F13,0) -> 0
A14: 11 | B14: 46214 | G14: =IFERROR(D14/F14,0) -> 0
A15: 12 | B15: 46215 | G15: =IFERROR(D15/F15,0) -> 0
... A19: 16 | B19: 46219 | G19: =IFERROR(D19/F19,0) -> 0
A20: 17 | B20: 46220 | G20: =IFERROR(#REF!/F20,0) -> 0
A21: 18 | B21: 46221 | G21: =IFERROR(D21/F21,0) -> 0
A22: 19 | B22: 46222 | G22: =IFERROR(D22/F22,0) -> 0
A23: 20 | B23: 46223 | G23: =IFERROR(D23/F23,0) -> 0
A24: 21 | B24: 46224 | G24: =IFERROR(D24/F24,0) -> 0
A25: 22 | B25: 46225 | G25: =IFERROR(D25/F25,0) -> 0
A26: 23 | B26: 46226 | G26: =IFERROR(D26/F26,0) -> 0
A27: 24 | B27: 46227 | G27: =IFERROR(D27/F27,0) -> 0
A28: 25 | B28: 46228 | G28: =IFERROR(D28/F28,0) -> 0
A29: 26 | B29: 46229 | G29: =IFERROR(D29/F29,0) -> 0
A30: 27 | B30: 46230 | G30: =IFERROR(D30/F30,0) -> 0
A31: 28 | B31: 46231 | G31: =IFERROR(D31/F31,0) -> 0
A32: 29 | B32: 46232 | G32: =IFERROR(D32/F32,0) -> 0
... A34: 31 | B34: 46234 | G34: =IFERROR(D34/F34,0) -> 0

Sheet Mẫu CT
A2: STT | B2: Số tài khoản | C2: Số Thẻ | D2: Số tiền chi tiêu hàng ngày theo đầu thẻ
D3: 46204 | E3: 46205 | F3: 46206 | G3: 46207 | H3: 46208 | I3: 46209 | J3: 46210 | K3: 46211 | L3: 46212 | M3: 46213 | N3: 46214 | O3: 46215 | P3: 46216 | Q3: 46217 | R3: 46218 | S3: 46219 | T3: 46220 | U3: 46221 | V3: 46222 | W3: 46223 | X3: 46224 | Y3: 46225 | Z3: 46226 | AA3: 46227 | AB3: 46228 | AC3: 46229 | AD3: 46230 | AE3: 46231 | AF3: 46232 | AG3: 46233 | AH3: 46234
A4: 1
A5: 2
A6: 3
A7: 4
A8: Tổng | C8: =+D8+E8+F8+G8+H8+I8+J8+K8+L8+M8+N8+O8++P8+Q8+R8+S8+T8+U8+V8+W8+X8+Y8+Z8+AA8+AB8+AC8+AD8+AE8+AF8+AG8+AH8 -> 0 | D8: =SUM(D4:D7) /1.1 -> 0 | E8: =SUM(E4:E7) /1.1 -> 0 | F8: =SUM(F4:F7) /1.1 -> 0 | G8: =SUM(G4:G7) /1.1 -> 0 | H8: =SUM(H4:H7) /1.1 -> 0 | I8: =SUM(I5:I7) /1.1 -> 0 | J8: =SUM(J4:J7) /1.1 -> 0 | K8: =SUM(K4:K7) /1.1 -> 0 | L8: =SUM(L4:L7) /1.1 -> 0 | M8: =SUM(M4:M7) /1.1 -> 0 | N8: =SUM(N4:N7) /1.1 -> 0 | O8: =SUM(O4:O7) /1.1 -> 0 | P8: =SUM(P4:P7) /1.1 -> 0 | Q8: =SUM(Q4:Q7) /1.1 -> 0 | ... AD8: =SUM(AD4:AD7) /1.1 -> 0 | AE8: =SUM(AE5:AE7) /1.1 -> 0 | AF8: =SUM(AF4:AF7) /1.1 -> 0 | AG8: =SUM(AG4:AG7) /1.1 -> 0 | AH8: =SUM(AH4:AH7) /1.1 -> 0
A9: Kế toán check Hóa đơn
A10: Chênh lệch | D10: =D8-D9 -> 0 | E10: =E8-E9 -> 0 | F10: =F8-F9 -> 0 | G10: =G8-G9 -> 0 | H10: =H8-H9 -> 0 | I10: =I8-I9 -> 0 | J10: =J8-J9 -> 0 | K10: =K8-K9 -> 0 | ... AH10: =AH8-AH9 -> 0
B13: Facebook Billing
B14: Ngày thanh toán | C14: Phương thức TT | D14: Số tham chiếu thẻ | E14: Số tiền | G14: Link thư mục ảnh hóa đơn

Sheet Thông tin ADS 
A1: STT | B1: Họ và tên | C1: TT Mail | D1: Số thẻ | E1: Số TK | F1: Tên Page | G1: Link Page | H1: Tên BM | I1: Tên TK QC | J1: Thời gian bắt đầu nhận ( điền với TH nhận page ngang trong tháng) | K1: LƯU Ý : NS chạy thêm tkqc , xây thêm page cần được duyệt bởi lãnh đạo . váo kế toán để thêm thông tin
A2: 1 | B2: Nguyễn Hoàng Anh | C2: anhnh.greenvita@gmail.com | F2: Bác Sĩ Hội - Chuyên Khoa Tiêu Hóa | G2: https://www.facebook.com/profile.php?id=61584406597552 | H2: BM BS Hội - Hưng Việt | I2: Hoàng Anh 1 - Hưng Việt
F3: Bác Sĩ Hội - Chuyên Khoa Tiêu Hóa | G3: https://www.facebook.com/profile.php?id=61580994806050 | H3: Hoàng Anh ADS - Green Vita | I3: Hoàng Anh ADS 01
F4: Bác sĩ Bách Hội | G4: https://www.facebook.com/bacsibachhoi | I4: Hoàng Anh ADS 02
F5: Bác Sĩ Hội - Phục Hồi Đại Tràng Từ Gốc | G5: https://www.facebook.com/profile.php?id=61585093756453 | I5: Hoàng Anh ADS 03
I6: Hoàng Anh ADS 04
I7: Hoàng Anh ADS 05
A8: 2 | B8: Nguyễn Thọ Thưởng | C8: thuongmkt42@gmail.com | F8: Bác sĩ Bách Hội - Phục Hồi Dạ Dày Từ Gốc | G8: https://www.facebook.com/bacsibachhoiphoidadaytugoc | I8: Thuong 3 -BM BS Hội - Hưng Việt
F9: BS Hội - Trung Tâm Tiêu Hóa | G9: https://www.facebook.com/profile.php?id=61588430593952 | I9: Thuong 2 -BM BS Hội - Hưng Việt
A12: 3 | B12: Bùi Quang Anh | C12: buiquanganh090901@gmail.com | F12: Bác Sĩ Hội - Sức Khỏe Đại Tràng & Tiêu Hóa | G12: https://www.facebook.com/profile.php?id=61587788227415 | H12: BM BS Hội - Hưng Việt | I12: Quang Anh 1 - BM BS Hội - Hưng Việt
F13: Bác sĩ Hội - Sức khỏe Dạ dày & Tiêu hóa | G13: https://www.facebook.com/profile.php?id=61580862672623 | I13: Quang Anh 2 - BM BS Hội - Hưng Việt
F14: Bác sĩ Nguyễn Bách Hội | G14: https://www.facebook.com/profile.php?id=61575705099170 | I14: Quang Anh 3 - BM BS Hội - Hưng Việt
H15: Quang Anh ADS - Green Vita | I15: Quang Anh 1 +7
A16: 4 | B16: Phạm Thế Hải | C16: phamthehai1494@gmail.com | F16: Bách Hội Chuyên Gia Dạ Dày & Tiêu Hóa | G16: https://www.facebook.com/bachhoidadaytieuhoa | H16: BM BS Hội - Hưng Việt | I16: Phạm Hải 1 -BM BS Hội - Hưng Việt
F17: Bác sĩ Hội - Giải pháp chăm sóc tiêu hóa | G17: https://www.facebook.com/profile.php?id=61586412321740 | H17: BM BS Hội - Hưng Việt | I17: Phạm Hải 2 -BM BS Hội - Hưng Việt
F18: Bác sĩ Hội - Chăm Sóc Sức Khỏe Đại Tràng Chuyên Sâu, Chuẩn Y Khoa | G18: https://www.facebook.com/bacsihoi.chamsocsuckhoedaitrangchuyensau | H18: BM BS Hội - Hưng Việt | I18: Phạm Hải 3 -BM BS Hội - Hưng Việt
H19: Bs Hội - BM Hải | I19: 632315609796394
A20: 5 | B20: Trần Quang Huy | C20: tuitenbear@gmail.com | F20: Bác sĩ Hội - Dạ dày & Tiêu hóa | G20: https://www.facebook.com/bacsihoidaday/ | H20: Hoàng Anh ADS - Green Vita | I20: Quang Huy 3 - Hưng Việt
F21: Dr Bách Hội | G21: https://www.facebook.com/bacsihoichuyendaday/ | I21: Quang Huy 2 - Hưng Việt
F22: Bác Sĩ Hội Tiêu Hóa Đại Tràng | G22: https://www.facebook.com/profile.php?id=61562973388499&locale=vi_VN | I22: Quang Huy 1 - Hưng Việt
F23: Dạ Dày Khỏe Cùng Bác Sĩ Hội | G23: https://www.facebook.com/profile.php?id=61578593195386 | I23: 01 Quang Huy ADS (+8)
A24: 6 | B24: Đỗ Quốc Anh | C24: doqanh2011@gmail.com | F24: Bác Sĩ Hội - BSCKI. Khoa Tiêu Hóa | G24: https://www.facebook.com/KhoaTieuHoa.BacSiHoi?locale=vi_VN | H24: Quốc Anh ADS - Green Vita | I24: 01 Quốc Anh ADS (+8)
F25: Bác sĩ Hội - Chuyên gia phục hồi sức khỏe dạy dày bền vững | G25: https://www.facebook.com/profile.php?id=61560743115486 | H25: BM BS Hội - Hưng Việt | I25: Quốc Anh 1 - Hưng Việt
I26: Quốc Anh 2 - Hưng Việt
I27: Quốc Anh 3 - Hưng Việt
A28: 7 | B28: Nguyễn Văn Lý | C28: lyn74502@gmail.com | F28: Bác sĩ Hội - Chuyên Gia Phục Hồi Về Sức Khỏe Đại Tràng | G28: https://www.facebook.com/profile.php?id=61589456031276 | H28: BM BS Hội - Hưng Việt | I28: Lý 1 -BM BS Hội - Hưng Việt
H29: Lý Nguyễn ADS - Green Vita | I29: Lý ADS - Green Vita 01
I30: Lý ADS - Green Vita 02
I31: Lý ADS - Green Vita 03
A32: 8
A36: 9
A40: 10
A44: 11

Sheet Kế hoạch tiêu $
A1: KẾ HOẠCH NGÂN SÁCH THÁNG 7
A2: STT | B2: Họ và tên | C2: Số tài khoản | D2: Số Thẻ | E2: Ngân sách /Tháng | F2: Ngân sách TB /Ngày | G2: Tuần 1 | H2: Tuần 2 | I2: Tuần 3 | J2: Tuần 4 | K2: Tuần 5 | L2: Doanh số | M2: Doanh số ngày | N2: Tỉ lệ CP | O2: DS THỰC TẾ | P2: Ngân sách đã tiêu | Q2: Tỉ lệ CP
A3: 1 | B3: Nguyễn Hoàng Anh | C3: 7923 - 065 | D3: 7923 | E3: =SUM(G3+H3+I3+J3+K3) -> 0 | F3: =E3/31 -> 0 | M3: =L3/31 -> 0 | N3: =E3/L3 -> #DIV/0! | O3: ='NH Anh T'!F3 -> 1124484021 | P3: ='NH Anh T'!D3 -> 7.9809915e+08 | Q3: =P3/O3 -> 0.70974699
A4: 2 | B4: Bùi Quang Anh | C4: 9793 - 081 | D4: 9793 | E4: =SUM(G4+H4+I4+J4+K4) -> 0 | F4: =E4/31 -> 0 | M4: =L4/31 -> 0 | N4: =E4/L4 -> #DIV/0! | O4: ='BQ Anh T'!F3 -> 520556882 | P4: ='BQ Anh T'!D3 -> 2.7254576e+08 | Q4: =P4/O4 -> 0.52356575
A5: 3 | B5: Trần Quang Huy | C5: 8384 - 057 | D5: 8384 | E5: =SUM(G5+H5+I5+J5+K5) -> 0 | F5: =E5/31 -> 0 | M5: =L5/31 -> 0 | N5: =E5/L5 -> #DIV/0! | O5: ='TQ Huy T'!F3 -> 408820000 | P5: ='TQ Huy T'!D3 -> 3.1075743e+08 | Q5: =P5/O5 -> 0.76013265
A6: 4 | B6: Phạm Thế Hải | C6: 8879 - 073 | D6: 8879 | E6: =SUM(G6+H6+I6+J6+K6) -> 0 | F6: =E6/31 -> 0 | M6: =L6/31 -> 0 | N6: =E6/L6 -> #DIV/0! | O6: ='PT Hải T'!F3 -> 366845000 | P6: ='PT Hải T'!D3 -> 270534090 | Q6: =P6/O6 -> 0.73746157
A7: 5 | B7: Nguyễn Văn Lý | C7: 1695 - 121 | D7: 1695 | E7: =SUM(G7+H7+I7+J7+K7) -> 0 | F7: =E7/31 -> 0 | M7: =L7/31 -> 0 | N7: =E7/L7 -> #DIV/0! | O7: ='NV Lý T'!F3 -> 47700000 | P7: ='NV Lý T'!D3 -> 35685695 | Q7: =P7/O7 -> 0.74812777
A8: 6 | B8: Đỗ Quốc Anh | C8: 9330 - 091 | D8: 9330 | E8: =SUM(G8+H8+I8+J8+K8) -> 0 | F8: =E8/31 -> 0 | M8: =L8/31 -> 0 | N8: =E8/L8 -> #DIV/0! | O8: ='ĐQ Anh T'!F3 -> 170205000 | P8: ='ĐQ Anh T'!D3 -> 91629632 | Q8: =P8/O8 -> 0.53834865
A9: 7 | E9: =SUM(G9+H9+I9+J9+K9) -> 0 | F9: =E9/31 -> 0 | M9: =L9/31 -> 0 | N9: =E9/L9 -> #DIV/0! | Q9: =P9/O9 -> #DIV/0!
A10: 8 | E10: =SUM(G10+H10+I10+J10+K10) -> 0 | F10: =E10/31 -> 0 | M10: =L10/31 -> 0 | N10: =E10/L10 -> #DIV/0! | Q10: =P10/O10 -> #DIV/0!
A11: TỔNG TEAM NT | E11: =SUM(E3:E10) -> 0 | F11: =SUM(F3:F10) -> 0 | G11: =SUM(G3:G10) -> 0 | H11: =SUM(H3:H10) -> 0 | I11: =SUM(I3:I10) -> 0 | J11: =SUM(J3:J10) -> 0 | K11: =SUM(K3:K10) -> 0 | L11: =SUM(L3:L10) -> 0 | M11: =SUM(M3:M10) -> 0 | N11: =E11/L11 -> #DIV/0! | O11: =SUM(O3:O10) -> 2638610903 | P11: =SUM(P3:P10) -> 1.7792517e+09 | Q11: =P11/O11 -> 0.6743138
A13: 1 | B13: Nguyễn Thọ Thưởng | D13: 2156 | E13: =SUM(G13+H13+I13+J13+K13) -> 0 | F13: =E13/31 -> 0 | M13: =L13/31 -> 0 | N13: =E13/L13 -> #DIV/0! | O13: ='NT Thưởng T'!F3 -> 93210000 | P13: ='NT Thưởng T'!D3 -> 1.1428408e+08 | Q13: =P13/O13 -> 1.2260925
A14: 2 | E14: =SUM(G14+H14+I14+J14+K14) -> 0 | F14: =E14/31 -> 0 | M14: =L14/31 -> 0 | N14: =E14/L14 -> #DIV/0! | Q14: =P14/O14 -> #DIV/0!
A15: 3 | E15: =SUM(G15+H15+I15+J15+K15) -> 0 | F15: =E15/31 -> 0 | M15: =L15/31 -> 0 | N15: =E15/L15 -> #DIV/0! | Q15: =P15/O15 -> #DIV/0!
A16: 4 | E16: =SUM(G16+H16+I16+J16+K16) -> 0 | F16: =E16/31 -> 0 | M16: =L16/31 -> 0 | N16: =E16/L16 -> #DIV/0! | Q16: =P16/O16 -> #DIV/0!
A17: 5 | E17: =SUM(G17+H17+I17+J17+K17) -> 0 | F17: =E17/31 -> 0 | M17: =L17/31 -> 0 | N17: =E17/L17 -> #DIV/0! | Q17: =P17/O17 -> #DIV/0!
A18: TỔNG TEAM OCP | E18: =SUM(E13:E17) -> 0 | F18: =SUM(F13:F17) -> 0 | G18: =SUM(G13:G17) -> 0 | H18: =SUM(H13:H17) -> 0 | I18: =SUM(I13:I17) -> 0 | J18: =SUM(J13:J17) -> 0 | K18: =SUM(K13:K17) -> 0 | L18: =SUM(L13:L17) -> 0 | M18: =SUM(M13:M17) -> 0 | N18: =E18/L18 -> #DIV/0! | O18: =SUM(O13:O17) -> 93210000 | P18: =SUM(P13:P17) -> 1.1428408e+08 | Q18: =P18/O18 -> 1.2260925
A20: TỔNG | E20: =E18+E11 -> 0 | F20: =F18+F11 -> 0 | G20: =G18+G11 -> 0 | H20: =H18+H11 -> 0 | I20: =I18+I11 -> 0 | J20: =J18+J11 -> 0 | K20: =K18+K11 -> 0 | L20: =L18+L11 -> 0 | M20: =M18+M11 -> 0 | N20: =E20/L20 -> #DIV/0! | O20: =O18+O11 -> 2731820903 | P20: =P18+P11 -> 1.8935358e+09 | Q20: =P20/O20 -> 0.69314054
A24: KẾ HOẠCH NGÂN SÁCH TUẦN 1
A25: STT | B25: Họ và tên | C25: Số tài khoản | D25: Số Thẻ | E25: Ngân sách /Tuần | F25: Thứ 2 | G25: Thứ 3 | H25: Thứ 4 | I25: Thứ 5 | J25: Thứ 6 | K25: Thứ 7 | L25: CN | M25: Tổng Doanh số (Cần Đạt) | N25: Doanh số ngày (Cần Đạt) | O25: Tỉ lệ CP | P25: DS THỰC TẾ | Q25: Ngân sách đã tiêu | R25: Tỉ lệ CP | S25: Dự trù ngân sách L1 (Ngày 01/07 - 02/07) | T25: Dự trù ngân sách L2 (Ngày 03/07 - 05/07)
A26: 1 | B26: Nguyễn Hoàng Anh | C26: 7923 - 065 | D26: 7923 | E26: =F26+G26+H26+I26+J26+K26+L26 -> 110000000 | F26: 0 | G26: 0 | H26: 22000000 | I26: 22000000 | J26: 22000000 | K26: 22000000 | L26: 22000000 | M26: 300000000 | N26: =M26/7 -> 42857143 | O26: =IFERROR(E26/M26,0) -> 0.36666667 | P26: ='Tổng tuần'!H3 -> 196595000 | Q26: ='Tổng tuần'!F3 -> 1.4547342e+08 | R26: =Q26/P26 -> 0.73996499 | S26: =SUM(F26:I26) -> 44000000 | T26: =SUM(J26:L26) -> 66000000
A27: 2 | B27: Bùi Quang Anh | C27: 9793 - 081 | D27: 9793 | E27: =F27+G27+H27+I27+J27+K27+L27 -> 60000000 | F27: 0 | G27: 0 | H27: 12000000 | I27: 12000000 | J27: 12000000 | K27: 12000000 | L27: 12000000 | M27: 170000000 | N27: =M27/7 -> 24285714 | O27: =IFERROR(E27/M27,0) -> 0.35294118 | P27: ='Tổng tuần'!H4 -> 42660000 | Q27: ='Tổng tuần'!F4 -> 64363971 | R27: =Q27/P27 -> 1.5087663 | S27: =SUM(F27:I27) -> 24000000 | T27: =SUM(J27:L27) -> 36000000
A28: 3 | B28: Trần Quang Huy | C28: 8384 - 057 | D28: 8384 | E28: =F28+G28+H28+I28+J28+K28+L28 -> 75000000 | F28: 0 | G28: 0 | H28: 15000000 | I28: 15000000 | J28: 15000000 | K28: 15000000 | L28: 15000000 | M28: 200000000 | N28: =M28/7 -> 28571429 | O28: =IFERROR(E28/M28,0) -> 0.375 | P28: ='Tổng tuần'!H5 -> 69345000 | Q28: ='Tổng tuần'!F5 -> 54895216 | R28: =Q28/P28 -> 0.79162472 | S28: =SUM(F28:I28) -> 30000000 | T28: =SUM(J28:L28) -> 45000000
A29: 4 | B29: Phạm Thế Hải | C29: 8879 - 073 | D29: 8879 | E29: =F29+G29+H29+I29+J29+K29+L29 -> 60000000 | F29: 0 | G29: 0 | H29: 12000000 | I29: 12000000 | J29: 12000000 | K29: 12000000 | L29: 12000000 | M29: 160000000 | N29: =M29/7 -> 22857143 | O29: =IFERROR(E29/M29,0) -> 0.375 | P29: ='Tổng tuần'!H6 -> 37740000 | Q29: ='Tổng tuần'!F6 -> 42710587 | R29: =Q29/P29 -> 1.1317061 | S29: =SUM(F29:I29) -> 24000000 | T29: =SUM(J29:L29) -> 36000000
A30: 5 | B30: Nguyễn Văn Lý | C30: 1695 - 121 | D30: 1695 | E30: =F30+G30+H30+I30+J30+K30+L30 -> 35000000 | F30: 0 | G30: 0 | H30: 7000000 | I30: 7000000 | J30: 7000000 | K30: 7000000 | L30: 7000000 | M30: 90000000 | N30: =M30/7 -> 12857143 | O30: =IFERROR(E30/M30,0) -> 0.38888889 | P30: ='Tổng tuần'!H7 -> 20025000 | Q30: ='Tổng tuần'!F7 -> 13879713 | R30: =Q30/P30 -> 0.69311924 | S30: =SUM(F30:I30) -> 14000000 | T30: =SUM(J30:L30) -> 21000000
A31: 6 | B31: Đỗ Quốc Anh | C31: 9330 - 091 | D31: 9330 | E31: =F31+G31+H31+I31+J31+K31+L31 -> 25000000 | F31: 0 | G31: 0 | H31: 5000000 | I31: 5000000 | J31: 5000000 | K31: 5000000 | L31: 5000000 | M31: 70000000 | N31: =M31/7 -> 10000000 | O31: =IFERROR(E31/M31,0) -> 0.35714286 | P31: ='Tổng tuần'!H8 -> 37855000 | Q31: ='Tổng tuần'!F8 -> 22099760 | R31: =Q31/P31 -> 0.58380029 | S31: =SUM(F31:I31) -> 10000000 | T31: =SUM(J31:L31) -> 15000000
A32: 7 | E32: =F32+G32+H32+I32+J32+K32+L32 -> 0 | N32: =M32/7 -> 0 | O32: =IFERROR(E32/M32,0) -> 0 | R32: =Q32/P32 -> #DIV/0! | S32: =SUM(F32:I32) -> 0 | T32: =SUM(J32:L32) -> 0
A33: 8 | E33: =F33+G33+H33+I33+J33+K33+L33 -> 0 | N33: =M33/7 -> 0 | O33: =IFERROR(E33/M33,0) -> 0 | R33: =Q33/P33 -> #DIV/0! | S33: =SUM(F33:I33) -> 0 | T33: =SUM(J33:L33) -> 0
A34: TỔNG TEAM NT | E34: =SUM(E26:E33) -> 365000000 | F34: =SUM(F26:F33) -> 0 | G34: =SUM(G26:G33) -> 0 | H34: =SUM(H26:H33) -> 73000000 | I34: =SUM(I26:I33) -> 73000000 | J34: =SUM(J26:J33) -> 73000000 | K34: =SUM(K26:K33) -> 73000000 | L34: =SUM(L26:L33) -> 73000000 | M34: =SUM(M26:M33) -> 990000000 | N34: =M34/7 -> 1.4142857e+08 | O34: =IFERROR(E34/M34,0) -> 0.36868687 | R34: =Q34/P34 -> #DIV/0! | S34: =SUM(F34:I34) -> 146000000 | T34: =SUM(J34:L34) -> 219000000
A36: 1 | B36: Nguyễn Thọ Thưởng | E36: =F36+G36+H36+I36+J36+K36+L36 -> 0 | N36: =M36/7 -> 0 | O36: =E36/M36 -> #DIV/0! | P36: ='Tổng tuần'!H13 -> 31780000 | Q36: ='Tổng tuần'!F13 -> 19610391 | R36: =Q36/P36 -> 0.61706705
A37: 2 | E37: =F37+G37+H37+I37+J37+K37+L37 -> 0 | N37: =M37/7 -> 0 | O37: =E37/M37 -> #DIV/0! | R37: =Q37/P37 -> #DIV/0!
A38: 3 | E38: =F38+G38+H38+I38+J38+K38+L38 -> 0 | N38: =M38/7 -> 0 | O38: =E38/M38 -> #DIV/0! | R38: =Q38/P38 -> #DIV/0!
A39: 4 | E39: =F39+G39+H39+I39+J39+K39+L39 -> 0 | N39: =M39/7 -> 0 | O39: =E39/M39 -> #DIV/0! | R39: =Q39/P39 -> #DIV/0!
A40: 5 | E40: =F40+G40+H40+I40+J40+K40+L40 -> 0 | N40: =M40/7 -> 0 | O40: =E40/M40 -> #DIV/0! | R40: =Q40/P40 -> #DIV/0!
A41: TỔNG TEAM OCP | E41: =SUM(E36:E40) -> 0 | F41: =SUM(F36:F40) -> 0 | G41: =SUM(G36:G40) -> 0 | H41: =SUM(H36:H40) -> 0 | I41: =SUM(I36:I40) -> 0 | J41: =SUM(J36:J40) -> 0 | K41: =SUM(K36:K40) -> 0 | L41: =SUM(L36:L40) -> 0 | M41: =SUM(M36:M40) -> 0 | N41: =M41/7 -> 0 | O41: =E41/M41 -> #DIV/0! | R41: =Q41/P41 -> #DIV/0!
A43: TỔNG | E43: =E41+E34 -> 365000000 | F43: =F41+F34 -> 0 | G43: =G41+G34 -> 0 | H43: =H41+H34 -> 73000000 | I43: =I41+I34 -> 73000000 | J43: =J41+J34 -> 73000000 | K43: =K41+K34 -> 73000000 | L43: =L41+L34 -> 73000000 | ... N43: =N41+N34 -> 1.4142857e+08 | O43: =E43/M43 -> 0.36868687 | P43: =P41+P34 -> 0 | Q43: =Q41+Q34 -> 0 | R43: =Q43/P43 -> #DIV/0! | S43: =S41+S34 -> 146000000 | T43: =T41+T34 -> 219000000
A46: KẾ HOẠCH NGÂN SÁCH TUẦN 2
A47: STT | B47: Họ và tên | C47: Số tài khoản | D47: Số Thẻ | E47: Ngân sách /Tuần | F47: Thứ 2 | G47: Thứ 3 | H47: Thứ 4 | I47: Thứ 5 | J47: Thứ 6 | K47: Thứ 7 | L47: CN | M47: Tổng Doanh số (Cần Đạt) | N47: Doanh số ngày (Cần Đạt) | O47: Tỉ lệ CP | P47: DS THỰC TẾ | Q47: Ngân sách đã tiêu | R47: Tỉ lệ CP | S47: Dự trù ngân sách L1 (Ngày 06/07 - 09/07) | T47: Dự trù ngân sách L2 (Ngày 10/07 - 12/07)
A48: 1 | B48: Nguyễn Hoàng Anh | C48: 7923 - 065 | D48: 7923 | E48: =F48+G48+H48+I48+J48+K48+L48 -> 154000000 | F48: 22000000 | G48: 22000000 | H48: 22000000 | I48: 22000000 | J48: 22000000 | K48: 22000000 | L48: 22000000 | M48: 300000000 | N48: =M48/7 -> 42857143 | O48: =E48/M48 -> 0.51333333 | P48: ='Tổng tuần'!M3 -> 273120000 | Q48: ='Tổng tuần'!K3 -> 1.9071843e+08 | R48: =Q48/P48 -> 0.69829537 | S48: =SUM(F48:I48) -> 88000000 | T48: =SUM(J48:L48) -> 66000000
A49: 2 | B49: Bùi Quang Anh | C49: 9793 - 081 | D49: 9793 | E49: =F49+G49+H49+I49+J49+K49+L49 -> 93000000 | F49: 12000000 | G49: 12000000 | H49: 12000000 | I49: 12000000 | J49: 15000000 | K49: 15000000 | L49: 15000000 | M49: 200000000 | N49: =M49/7 -> 28571429 | O49: =E49/M49 -> 0.465 | P49: ='Tổng tuần'!M4 -> 138775000 | Q49: ='Tổng tuần'!K4 -> 71726646 | R49: =Q49/P49 -> 0.51685568 | S49: =SUM(F49:I49) -> 48000000 | T49: =SUM(J49:L49) -> 45000000
...

Sheet Tổng tuần
E1: Tuần 1 | J1: Tuần 2 | O1: Tuần 3 | T1: Tuần 4 | Y1: Tuần 5
A2: STT | B2: Họ và tên | C2: Số tài khoản | D2: Số Thẻ | E2: Ngân sách cấp | F2: Ngân sách đã tiêu | G2: Số đơn | H2: Doanh số | I2: Tỷ lệ CP | J2: Ngân sách cấp | K2: Ngân sách đã tiêu | L2: Số đơn | M2: Doanh số | N2: Tỷ lệ CP | O2: Ngân sách cấp | P2: Ngân sách đã tiêu | Q2: Số đơn | R2: Doanh số | S2: Tỷ lệ CP | T2: Ngân sách cấp | U2: Ngân sách đã tiêu | V2: Số đơn | W2: Doanh số | X2: Tỷ lệ CP | Y2: Ngân sách cấp | Z2: Ngân sách đã tiêu | AA2: Số đơn | AB2: Doanh số | AC2: Tỷ lệ CP
A3: 1 | B3: Nguyễn Hoàng Anh | E3: =SUM('NH Anh T'!C4:C8) -> 110000000 | F3: =SUM('NH Anh T'!D4:D8) -> 1.4547342e+08 | G3: =SUM('NH Anh T'!E4:E8) -> 62 | H3: =SUM('NH Anh T'!F4:F8) -> 196595000 | I3: =F3/H3 -> 0.73996499 | J3: =SUM('NH Anh T'!C9:C15) -> 88000000 | K3: =SUM('NH Anh T'!D9:D15) -> 1.9071843e+08 | L3: =SUM('NH Anh T'!E9:E15) -> 88 | M3: =SUM('NH Anh T'!F9:F15) -> 273120000 | N3: =K3/M3 -> 0.69829537 | O3: =SUM('NH Anh T'!C16:C22) -> 0 | P3: =SUM('NH Anh T'!D16:D22) -> 1.70132e+08 | Q3: =SUM('NH Anh T'!E16:E22) -> 93 | R3: =SUM('NH Anh T'!F16:F22) -> 299595000 | S3: =P3/R3 -> 0.5678733 | T3: =SUM('NH Anh T'!C23:C29) -> 0 | U3: =SUM('NH Anh T'!D23:D29) -> 1.7622495e+08 | V3: =SUM('NH Anh T'!E23:E29) -> 100 | W3: =SUM('NH Anh T'!F23:F29) -> 314980000 | X3: =U3/W3 -> 0.55947982 | Y3: =SUM('NH Anh T'!C30:C34) -> 0 | Z3: =SUM('NH Anh T'!D30:D34) -> 1.1555034e+08 | AA3: =SUM('NH Anh T'!E30:E34) -> 56 | AB3: =SUM('NH Anh T'!F30:F34) -> 180675000 | AC3: =Z3/AB3 -> 0.63954805
A4: 2 | B4: Bùi Quang Anh | E4: =SUM('BQ Anh T'!C4:C8) -> 65000000 | F4: =SUM('BQ Anh T'!D4:D8) -> 64363971 | G4: =SUM('BQ Anh T'!E4:E8) -> 20 | H4: =SUM('BQ Anh T'!F4:F8) -> 42660000 | I4: =F4/H4 -> 1.5087663 | J4: =SUM('BQ Anh T'!C9:C15) -> 48000000 | K4: =SUM('BQ Anh T'!D9:D15) -> 71726646 | L4: =SUM('BQ Anh T'!E9:E15) -> 49 | M4: =SUM('BQ Anh T'!F9:F15) -> 138775000 | N4: =K4/M4 -> 0.51685568 | O4: =SUM('BQ Anh T'!C16:C22) -> 0 | P4: =SUM('BQ Anh T'!D16:D22) -> 57009801 | Q4: =SUM('BQ Anh T'!E16:E22) -> 32 | R4: =SUM('BQ Anh T'!F16:F22) -> 68880000 | S4: =P4/R4 -> 0.82766842 | T4: =SUM('BQ Anh T'!C23:C29) -> 0 | U4: =SUM('BQ Anh T'!D23:D29) -> 58518396 | V4: =SUM('BQ Anh T'!E23:E29) -> 45 | W4: =SUM('BQ Anh T'!F23:F29) -> 137545000 | X4: =U4/W4 -> 0.4254491 | Y4: =SUM('BQ Anh T'!C30:C34) -> 0 | Z4: =SUM('BQ Anh T'!D30:D34) -> 20926941 | AA4: =SUM('BQ Anh T'!E30:E34) -> 22 | AB4: =SUM('BQ Anh T'!F30:F34) -> 75084696 | AC4: =Z4/AB4 -> 0.27871114
A5: 3 | B5: Trần Quang Huy | E5: =SUM('TQ Huy T'!C4:C8) -> 75000000 | F5: =SUM('TQ Huy T'!D4:D8) -> 54895216 | G5: =SUM('TQ Huy T'!E4:E8) -> 22 | H5: =SUM('TQ Huy T'!F4:F8) -> 69345000 | I5: =F5/H5 -> 0.79162472 | J5: =SUM('TQ Huy T'!C9:C15) -> 105000000 | K5: =SUM('TQ Huy T'!D9:D15) -> 66971431 | L5: =SUM('TQ Huy T'!E9:E15) -> 24 | M5: =SUM('TQ Huy T'!F9:F15) -> 77165000 | N5: =K5/M5 -> 0.86789906 | O5: =SUM('TQ Huy T'!C16:C22) -> 66000000 | P5: =SUM('TQ Huy T'!D16:D22) -> 68898529 | Q5: =SUM('TQ Huy T'!E16:E22) -> 26 | R5: =SUM('TQ Huy T'!F16:F22) -> 85635000 | S5: =P5/R5 -> 0.80456039 | T5: =SUM('TQ Huy T'!C23:C29) -> 0 | U5: =SUM('TQ Huy T'!D23:D29) -> 58942431 | V5: =SUM('TQ Huy T'!E23:E29) -> 29 | W5: =SUM('TQ Huy T'!F23:F29) -> 96445000 | X5: =U5/W5 -> 0.61115072 | Y5: =SUM('TQ Huy T'!C30:C34) -> 0 | Z5: =SUM('TQ Huy T'!D30:D34) -> 61049821 | AA5: =SUM('TQ Huy T'!E30:E34) -> 0 | AB5: =SUM('TQ Huy T'!F30:F34) -> 80230000 | AC5: =Z5/AB5 -> 0.76093507
A6: 4 | B6: Phạm Thế Hải | E6: =SUM('PT Hải T'!C4:C8) -> 24000000 | F6: =SUM('PT Hải T'!D4:D8) -> 42710587 | G6: =SUM('PT Hải T'!E4:E8) -> 12 | H6: =SUM('PT Hải T'!F4:F8) -> 37740000 | I6: =F6/H6 -> 1.1317061 | J6: =SUM('PT Hải T'!C9:C15) -> 0 | K6: =SUM('PT Hải T'!D9:D15) -> 55419126 | L6: =SUM('PT Hải T'!E9:E15) -> 21 | M6: =SUM('PT Hải T'!F9:F15) -> 64845000 | N6: =K6/M6 -> 0.85463993 | O6: =SUM('PT Hải T'!C16:C22) -> 0 | P6: =SUM('PT Hải T'!D16:D22) -> 54678749 | Q6: =SUM('PT Hải T'!E16:E22) -> 19 | R6: =SUM('PT Hải T'!F16:F22) -> 58745000 | S6: =P6/R6 -> 0.93078133 | T6: =SUM('PT Hải T'!C23:C29) -> 0 | U6: =SUM('PT Hải T'!D23:D29) -> 89627057 | V6: =SUM('PT Hải T'!E23:E29) -> 33 | W6: =SUM('PT Hải T'!F23:F29) -> 117945000 | X6: =U6/W6 -> 0.75990553 | Y6: =SUM('PT Hải T'!C30:C34) -> 0 | Z6: =SUM('PT Hải T'!D30:D34) -> 28098570 | AA6: =SUM('PT Hải T'!E30:E34) -> 15 | AB6: =SUM('PT Hải T'!F30:F34) -> 52570000 | AC6: =Z6/AB6 -> 0.53449819
A7: 5 | B7: Nguyễn Văn Lý | E7: =SUM('NV Lý T'!C4:C8) -> 7000000 | F7: =SUM('NV Lý T'!D4:D8) -> 13879713 | G7: =SUM('NV Lý T'!E4:E8) -> 7 | H7: =SUM('NV Lý T'!F4:F8) -> 20025000 | I7: =F7/H7 -> 0.69311924 | J7: =SUM('NV Lý T'!C9:C15) -> 0 | K7: =SUM('NV Lý T'!D9:D15) -> 21805982 | L7: =SUM('NV Lý T'!E9:E15) -> 5 | M7: =SUM('NV Lý T'!F9:F15) -> 20935000 | N7: =K7/M7 -> 1.0416041 | O7: =SUM('NV Lý T'!C16:C22) -> 0 | P7: =SUM('NV Lý T'!D16:D22) -> 0 | Q7: =SUM('NV Lý T'!E16:E22) -> 0 | R7: =SUM('NV Lý T'!F16:F22) -> 6740000 | S7: =P7/R7 -> 0 | T7: =SUM('NV Lý T'!C23:C29) -> 0 | U7: =SUM('NV Lý T'!D23:D29) -> 0 | V7: =SUM('NV Lý T'!E23:E29) -> 0 | W7: =SUM('NV Lý T'!F23:F29) -> 0 | X7: =U7/W7 -> #DIV/0! | Y7: =SUM('NV Lý T'!C30:C34) -> 0 | Z7: =SUM('NV Lý T'!D30:D34) -> 0 | AA7: =SUM('NV Lý T'!E30:E34) -> 0 | AB7: =SUM('NV Lý T'!F30:F34) -> 0 | AC7: =Z7/AB7 -> #DIV/0!
A8: 6 | B8: Đỗ Quốc Anh | E8: =SUM('ĐQ Anh T'!C4:C8) -> 25000000 | F8: =SUM('ĐQ Anh T'!D4:D8) -> 22099760 | G8: =SUM('ĐQ Anh T'!E4:E8) -> 11 | H8: =SUM('ĐQ Anh T'!F4:F8) -> 37855000 | I8: =F8/H8 -> 0.58380029 | J8: =SUM('ĐQ Anh T'!C9:C15) -> 35000000 | K8: =SUM('ĐQ Anh T'!D9:D15) -> 29074899 | L8: =SUM('ĐQ Anh T'!E9:E15) -> 13 | M8: =SUM('ĐQ Anh T'!F9:F15) -> 47040000 | N8: =K8/M8 -> 0.61808884 | O8: =SUM('ĐQ Anh T'!C16:C22) -> 28000000 | P8: =SUM('ĐQ Anh T'!D16:D22) -> 18771075 | Q8: =SUM('ĐQ Anh T'!E16:E22) -> 10 | R8: =SUM('ĐQ Anh T'!F16:F22) -> 36270000 | S8: =P8/R8 -> 0.51753721 | T8: =SUM('ĐQ Anh T'!C23:C29) -> 12000000 | U8: =SUM('ĐQ Anh T'!D23:D29) -> 21683898 | V8: =SUM('ĐQ Anh T'!E23:E29) -> 8 | W8: =SUM('ĐQ Anh T'!F23:F29) -> 34770000 | X8: =U8/W8 -> 0.62363814 | Y8: =SUM('ĐQ Anh T'!C30:C34) -> 0 | Z8: =SUM('ĐQ Anh T'!D30:D34) -> 0 | AA8: =SUM('ĐQ Anh T'!E30:E34) -> 0 | AB8: =SUM('ĐQ Anh T'!F30:F34) -> 14270000 | AC8: =Z8/AB8 -> 0
A9: 7 | I9: =F9/H9 -> #DIV/0! | N9: =K9/M9 -> #DIV/0! | S9: =P9/R9 -> #DIV/0! | X9: =U9/W9 -> #DIV/0! | AC9: =Z9/AB9 -> #DIV/0!
A10: 8 | I10: =F10/H10 -> #DIV/0! | N10: =K10/M10 -> #DIV/0! | S10: =P10/R10 -> #DIV/0! | X10: =U10/W10 -> #DIV/0! | AC10: =Z10/AB10 -> #DIV/0!
A11: TỔNG TEAM NT | E11: =SUM(E3:E10) -> 306000000 | F11: =SUM(F3:F10) -> 3.4342266e+08 | G11: =SUM(G3:G10) -> 134 | H11: =SUM(H3:H10) -> 404220000 | I11: =F11/H11 -> 0.84959345 | J11: =SUM(J3:J10) -> 276000000 | K11: =SUM(K3:K10) -> 4.3571652e+08 | L11: =SUM(L3:L10) -> 200 | M11: =SUM(M3:M10) -> 621880000 | N11: =K11/M11 -> 0.70064404 | O11: =SUM(O3:O10) -> 94000000 | P11: =SUM(P3:P10) -> 3.6949016e+08 | Q11: =SUM(Q3:Q10) -> 180 | R11: =SUM(R3:R10) -> 555865000 | S11: =P11/R11 -> 0.66471204 | T11: =SUM(T3:T10) -> 12000000 | U11: =SUM(U3:U10) -> 4.0499674e+08 | V11: =SUM(V3:V10) -> 215 | W11: =SUM(W3:W10) -> 701685000 | X11: =U11/W11 -> 0.57717742 | Y11: =SUM(Y3:Y10) -> 0 | Z11: =SUM(Z3:Z10) -> 2.2562568e+08 | AA11: =SUM(AA3:AA10) -> 93 | AB11: =SUM(AB3:AB10) -> 402829696 | AC11: =Z11/AB11 -> 0.56010189
A13: 1 | B13: Nguyễn Thọ Thưởng | E13: =SUM('NT Thưởng T'!C4:C8) -> 0 | F13: =SUM('NT Thưởng T'!D4:D8) -> 19610391 | G13: =SUM('NT Thưởng T'!E4:E8) -> 10 | H13: =SUM('NT Thưởng T'!F4:F8) -> 31780000 | I13: =F13/H13 -> 0.61706705 | J13: =SUM('NT Thưởng T'!C9:C15) -> 0 | K13: =SUM('NT Thưởng T'!D9:D15) -> 27648778 | L13: =SUM('NT Thưởng T'!E9:E15) -> 4 | M13: =SUM('NT Thưởng T'!F9:F15) -> 12290000 | N13: =K13/M13 -> 2.2496972 | O13: =SUM('NT Thưởng T'!C16:C22) -> 0 | P13: =SUM('NT Thưởng T'!D16:D22) -> 16293303 | Q13: =SUM('NT Thưởng T'!E16:E22) -> 7 | R13: =SUM('NT Thưởng T'!F16:F22) -> 20115000 | S13: =P13/R13 -> 0.81000759 | T13: =SUM('NT Thưởng T'!C23:C29) -> 0 | U13: =SUM('NT Thưởng T'!D23:D29) -> 40040905 | V13: =SUM('NT Thưởng T'!E23:E29) -> 6 | W13: =SUM('NT Thưởng T'!F23:F29) -> 15815000 | X13: =U13/W13 -> 2.5318309 | Y13: =SUM('NT Thưởng T'!C30:C34) -> 0 | Z13: =SUM('NT Thưởng T'!D30:D34) -> 10690703 | AA13: =SUM('NT Thưởng T'!E30:E34) -> 4 | AB13: =SUM('NT Thưởng T'!F30:F34) -> 13210000 | AC13: =Z13/AB13 -> 0.80928862
A14: 2 | I14: =F14/H14 -> #DIV/0! | N14: =K14/M14 -> #DIV/0! | S14: =P14/R14 -> #DIV/0! | X14: =U14/W14 -> #DIV/0! | AC14: =Z14/AB14 -> #DIV/0!
A15: 3 | I15: =F15/H15 -> #DIV/0! | N15: =K15/M15 -> #DIV/0! | S15: =P15/R15 -> #DIV/0! | X15: =U15/W15 -> #DIV/0! | AC15: =Z15/AB15 -> #DIV/0!
A16: 4 | I16: =F16/H16 -> #DIV/0! | N16: =K16/M16 -> #DIV/0! | S16: =P16/R16 -> #DIV/0! | X16: =U16/W16 -> #DIV/0! | AC16: =Z16/AB16 -> #DIV/0!
A17: 5 | I17: =F17/H17 -> #DIV/0! | N17: =K17/M17 -> #DIV/0! | S17: =P17/R17 -> #DIV/0! | X17: =U17/W17 -> #DIV/0! | AC17: =Z17/AB17 -> #DIV/0!
A18: TỔNG TEAM OCP | E18: =SUM(E13:E17) -> 0 | F18: =SUM(F13:F17) -> 19610391 | G18: =SUM(G13:G17) -> 10 | H18: =SUM(H13:H17) -> 31780000 | I18: =F18/H18 -> 0.61706705 | J18: =SUM(J13:J17) -> 0 | K18: =SUM(K13:K17) -> 27648778 | L18: =SUM(L13:L17) -> 4 | M18: =SUM(M13:M17) -> 12290000 | N18: =K18/M18 -> 2.2496972 | O18: =SUM(O13:O17) -> 0 | P18: =SUM(P13:P17) -> 16293303 | Q18: =SUM(Q13:Q17) -> 7 | R18: =SUM(R13:R17) -> 20115000 | S18: =P18/R18 -> 0.81000759 | T18: =SUM(T13:T17) -> 0 | U18: =SUM(U13:U17) -> 40040905 | V18: =SUM(V13:V17) -> 6 | W18: =SUM(W13:W17) -> 15815000 | X18: =U18/W18 -> 2.5318309 | Y18: =SUM(Y13:Y17) -> 0 | Z18: =SUM(Z13:Z17) -> 10690703 | AA18: =SUM(AA13:AA17) -> 4 | AB18: =SUM(AB13:AB17) -> 13210000 | AC18: =Z18/AB18 -> 0.80928862
A20: TỔNG | E20: =E18+E11 -> 306000000 | F20: =F18+F11 -> 3.6303305e+08 | G20: =G18+G11 -> 144 | H20: =H18+H11 -> 436000000 | I20: =F20/H20 -> 0.83264462 | J20: =J18+J11 -> 276000000 | K20: =K18+K11 -> 4.633653e+08 | L20: =L18+L11 -> 204 | M20: =M18+M11 -> 634170000 | N20: =K20/M20 -> 0.73066417 | O20: =O18+O11 -> 94000000 | P20: =P18+P11 -> 3.8578346e+08 | Q20: =Q18+Q11 -> 187 | R20: =R18+R11 -> 575980000 | S20: =P20/R20 -> 0.6697862 | T20: =T18+T11 -> 12000000 | U20: =U18+U11 -> 4.4503764e+08 | V20: =V18+V11 -> 221 | W20: =W18+W11 -> 717500000 | X20: =U20/W20 -> 0.62026152 | Y20: =Y18+Y11 -> 0 | Z20: =Z18+Z11 -> 2.3631638e+08 | AA20: =AA18+AA11 -> 97 | AB20: =AB18+AB11 -> 416039696 | AC20: =Z20/AB20 -> 0.56801402
E23: Tổng chi tiêu tháng
A24: STT | B24: Họ và tên | C24: Số tài khoản | D24: Số Thẻ | E24: Ngân sách cấp | F24: Ngân sách đã tiêu | G24: Số đơn | H24: Doanh số | I24: Tỷ lệ CP
A25: 1 | B25: Nguyễn Hoàng Anh | E25: =SUM('NH Anh T'!C3) -> 198000000 | F25: =SUM('NH Anh T'!D3) -> 7.9809915e+08 | G25: =SUM('NH Anh T'!E3) -> 399 | H25: =SUM('NH Anh T'!F3) -> 1124484021 | I25: =F25/H25 -> 0.70974699
A26: 2 | B26: Bùi Quang Anh | E26: =SUM('BQ Anh T'!C3) -> 113000000 | F26: =SUM('BQ Anh T'!D3) -> 2.7254576e+08 | G26: =SUM('BQ Anh T'!E3) -> 168 | H26: =SUM('BQ Anh T'!F3) -> 520556882 | I26: =F26/H26 -> 0.52356575
A27: 3 | B27: Trần Quang Huy | E27: =SUM('TQ Huy T'!C3) -> 246000000 | F27: =SUM('TQ Huy T'!D3) -> 3.1075743e+08 | G27: =SUM('TQ Huy T'!E3) -> 101 | H27: =SUM('TQ Huy T'!F3) -> 408820000 | I27: =F27/H27 -> 0.76013265
A28: 4 | B28: Phạm Thế Hải | E28: =SUM('PT Hải T'!C3) -> 24000000 | F28: =SUM('PT Hải T'!D3) -> 270534090 | G28: =SUM('PT Hải T'!E3) -> 100 | H28: =SUM('PT Hải T'!F3) -> 366845000 | I28: =F28/H28 -> 0.73746157
A29: 5 | B29: Nguyễn Văn Lý | E29: =SUM('NV Lý T'!C3) -> 7000000 | F29: =SUM('NV Lý T'!D3) -> 35685695 | G29: =SUM('NV Lý T'!E3) -> 12 | H29: =SUM('NV Lý T'!F3) -> 47700000 | I29: =F29/H29 -> 0.74812777
A30: 6 | B30: Đỗ Quốc Anh | E30: =SUM('ĐQ Anh T'!C3) -> 100000000 | F30: =SUM('ĐQ Anh T'!D3) -> 91629632 | G30: =SUM('ĐQ Anh T'!E3) -> 42 | H30: =SUM('ĐQ Anh T'!F3) -> 170205000 | I30: =F30/H30 -> 0.53834865
A31: 7 | I31: =F31/H31 -> #DIV/0!
A32: 8 | I32: =F32/H32 -> #DIV/0!
A33: TỔNG TEAM NT | E33: =SUM(E25:E32) -> 688000000 | F33: =SUM(F25:F32) -> 1.7792517e+09 | G33: =SUM(G25:G32) -> 822 | H33: =SUM(H25:H32) -> 2638610903 | I33: =F33/H33 -> 0.6743138
A35: 1 | B35: Nguyễn Thọ Thưởng | E35: =SUM('NT Thưởng T'!C11) -> 0 | F35: =SUM('NT Thưởng T'!D3) -> 1.1428408e+08 | G35: =SUM('NT Thưởng T'!E3) -> 31 | H35: =SUM('NT Thưởng T'!F3) -> 93210000 | I35: =F35/H35 -> 1.2260925
A36: 2 | I36: =F36/H36 -> #DIV/0!
A37: 3 | I37: =F37/H37 -> #DIV/0!
A38: 4 | I38: =F38/H38 -> #DIV/0!
A39: 5 | I39: =F39/H39 -> #DIV/0!
A40: TỔNG TEAM OCP | E40: =SUM(E35:E39) -> 0 | F40: =SUM(F35:F39) -> 1.1428408e+08 | G40: =SUM(G35:G39) -> 31 | H40: =SUM(H35:H39) -> 93210000 | I40: =F40/H40 -> 1.2260925
A42: TỔNG | E42: =E40+E33 -> 688000000 | F42: =F40+F33 -> 1.8935358e+09 | G42: =G40+G33 -> 853 | H42: =H40+H33 -> 2731820903 | I42: =F42/H42 -> 0.69314054

Sheet BC hàng ngày
C1: BÁO CÁO HÀNG NGÀY
A2: STT | B2: Họ và tên | C2: Tổng doanh thu tháng | D2: Tổng ngân sách đã chi tiêu | E2: Ngân sách đã tiêu | F2: Số đơn | G2: Doanh số | H2: Tỷ lệ CP
A3: 1 | B3: Nguyễn Hoàng Anh | C3: =SUM('NH Anh T'!F3) -> 1124484021 | D3: =SUM('NH Anh T'!D3) -> 7.9809915e+08 | E3: =SUM('NH Anh T'!D33) -> 37684788 | F3: =SUM('NH Anh T'!E33) -> 23 | G3: =SUM('NH Anh T'!F33) -> 72730000 | H3: =E3/G3 -> 0.51814641
A4: 2 | B4: Bùi Quang Anh | C4: =SUM('BQ Anh T'!F3) -> 520556882 | D4: =SUM('BQ Anh T'!D3) -> 2.7254576e+08 | E4: =SUM('BQ Anh T'!D33) -> 0 | F4: =SUM('BQ Anh T'!E33) -> 4 | G4: =SUM('BQ Anh T'!F33) -> 12680000 | H4: =E4/G4 -> 0
A5: 3 | B5: Trần Quang Huy | C5: =SUM('TQ Huy T'!F3) -> 408820000 | D5: =SUM('TQ Huy T'!D3) -> 3.1075743e+08 | E5: =SUM('TQ Huy T'!D33) -> 24979795 | F5: =SUM('TQ Huy T'!E33) -> 0 | G5: =SUM('TQ Huy T'!F33) -> 14350000 | H5: =E5/G5 -> 1.7407522
A6: 4 | B6: Phạm Thế Hải | C6: =SUM('PT Hải T'!F3) -> 366845000 | D6: =SUM('PT Hải T'!D3) -> 270534090 | E6: =SUM('PT Hải T'!D33) -> 0 | F6: =SUM('PT Hải T'!E33) -> 3 | G6: =SUM('PT Hải T'!F33) -> 10370000 | H6: =E6/G6 -> 0
A7: 5 | B7: Nguyễn Văn Lý | C7: =SUM('NV Lý T'!F3) -> 47700000 | D7: =SUM('NV Lý T'!D3) -> 35685695 | E7: =SUM('NV Lý T'!D17) -> 0 | F7: =SUM('NV Lý T'!E17) -> 0 | G7: =SUM('NV Lý T'!F17) -> 0 | H7: =E7/G7 -> #DIV/0!
A8: 6 | B8: Đỗ Quốc Anh | C8: =SUM('ĐQ Anh T'!F3) -> 170205000 | D8: =SUM('ĐQ Anh T'!D3) -> 91629632 | E8: =SUM('ĐQ Anh T'!D33) -> 0 | F8: =SUM('ĐQ Anh T'!E33) -> 0 | G8: =SUM('ĐQ Anh T'!F33) -> 3330000 | H8: =E8/G8 -> 0
A9: 7 | H9: =E9/G9 -> #DIV/0!
A10: 8 | H10: =E10/G10 -> #DIV/0!
A11: TỔNG TEAM NT | C11: =SUM(C3:C10) -> 2638610903 | D11: =SUM(D3:D10) -> 1.7792517e+09 | E11: =SUM(E3:E10) -> 62664583 | F11: =SUM(F3:F10) -> 30 | G11: =SUM(G3:G10) -> 113460000 | H11: =E11/G11 -> 0.55230551
A13: 1 | B13: Nguyễn Thọ Thưởng | C13: =SUM('NT Thưởng T'!F3) -> 93210000 | D13: =SUM('NT Thưởng T'!D3) -> 1.1428408e+08 | E13: =SUM('NT Thưởng T'!D33) -> 0 | F13: =SUM('NT Thưởng T'!E33) -> 1 | G13: =SUM('NT Thưởng T'!F33) -> 3560000 | H13: =E13/G13 -> 0
A14: 2 | H14: =E14/G14 -> #DIV/0!
A15: 3 | H15: =E15/G15 -> #DIV/0!
A16: 4 | H16: =E16/G16 -> #DIV/0!
A17: 5 | H17: =E17/G17 -> #DIV/0!
A18: TỔNG TEAM OCP | C18: =SUM(C13:C17) -> 93210000 | D18: =SUM(D13:D17) -> 1.1428408e+08 | E18: =SUM(E13:E17) -> 0 | F18: =SUM(F13:F17) -> 1 | G18: =SUM(G13:G17) -> 3560000 | H18: =E18/G18 -> 0
A20: TỔNG | C20: =C18+C11 -> 2731820903 | E20: =E18+E11 -> 62664583 | F20: =F18+F11 -> 31 | G20: =G18+G11 -> 117020000 | H20: =E20/G20 -> 0.53550319

Sheet NH Anh T
A2: STT | B2: Ngày/tháng | C2: Ngân sách cấp | D2: Tổng đã tiêu | E2: Số đơn | F2: Doanh số | G2: Tỷ lệ CP
C3: =+SUM(C4:C34) -> 198000000 | D3: =SUM(D4:D34) -> 7.9809915e+08 | E3: =SUM(E4:E34) -> 399 | F3: =SUM(F4:F36) -> 1124484021 | G3: =IFERROR(D3/F3,0) -> 0.70974699 | H3: =SUM(H4:H36) -> 269705000
A4: 1 | B4: 46204 | C4: 44000000 | D4: ='NH Anh CT'!D17 -> 48972523 | E4: 7 | F4: 23975000 | G4: =IFERROR(D4/F4,0) -> 2.0426495 | H4: 3375000 | I4: =F4-H4 -> 20600000
A5: 2 | B5: 46205 | D5: ='NH Anh CT'!E17 -> 36598003 | E5: 14 | F5: 45590000 | G5: =IFERROR(D5/F5,0) -> 0.80276382 | H5: 13050000 | I5: =F5-H5 -> 32540000
A6: 3 | B6: 46206 | C6: 66000000 | D6: ='NH Anh CT'!F17 -> 13933988 | E6: 20 | F6: 63165000 | G6: =IFERROR(D6/F6,0) -> 0.22059666 | H6: 24780000 | I6: =F6-H6 -> 38385000
A7: 4 | B7: 46207 | D7: ='NH Anh CT'!G17 -> 26869589 | E7: 8 | F7: 26005000 | G7: =IFERROR(D7/F7,0) -> 1.033247 | H7: 3375000 | I7: =F7-H7 -> 22630000
A8: 5 | B8: 46208 | D8: ='NH Anh CT'!H17 -> 19099314 | E8: 13 | F8: 37860000 | G8: =IFERROR(D8/F8,0) -> 0.5044721 | H8: 8530000 | I8: =F8-H8 -> 29330000
A9: 6 | B9: 46209 | C9: 88000000 | D9: ='NH Anh CT'!I17 -> 31317289 | E9: 6 | F9: 20665000 | G9: =IFERROR(D9/F9,0) -> 1.5154749 | H9: 10640000 | I9: =F9-H9 -> 10025000
A10: 7 | B10: 46210 | D10: ='NH Anh CT'!J17 -> 32464935 | E10: 20 | F10: 60085000 | G10: =IFERROR(D10/F10,0) -> 0.54031681 | H10: 12630000 | I10: =F10-H10 -> 47455000
A11: 8 | B11: 46211 | D11: ='NH Anh CT'!K17 -> 21969305 | E11: 16 | F11: 49510000 | G11: =IFERROR(D11/F11,0) -> 0.44373471 | H11: 9445000 | I11: =F11-H11 -> 40065000
A12: 9 | B12: 46212 | D12: ='NH Anh CT'!L17 -> 34078275 | E12: 8 | F12: 23270000 | G12: =IFERROR(D12/F12,0) -> 1.4644725 | H12: 5820000 | I12: =F12-H12 -> 17450000
A13: 10 | B13: 46213 | D13: ='NH Anh CT'!M17 -> 24759421 | E13: 9 | F13: 27925000 | G13: =IFERROR(D13/F13,0) -> 0.88663996 | I13: =F13-H13 -> 27925000
A14: 11 | B14: 46214 | D14: ='NH Anh CT'!N17 -> 21841721 | E14: 19 | F14: 59780000 | G14: =IFERROR(D14/F14,0) -> 0.36536837 | H14: 12420000 | I14: =F14-H14 -> 47360000
A15: 12 | B15: 46215 | D15: ='NH Anh CT'!O17 -> 24287485 | E15: 10 | F15: 31885000 | G15: =IFERROR(D15/F15,0) -> 0.76172136 | H15: 13410000 | I15: =F15-H15 -> 18475000
A16: 13 | B16: 46216 | D16: ='NH Anh CT'!P17 -> 22379704 | E16: 8 | F16: 25210000 | G16: =IFERROR(D16/F16,0) -> 0.8877312 | H16: 6970000 | I16: =F16-H16 -> 18240000
A17: 14 | B17: 46217 | D17: ='NH Anh CT'!Q17 -> 31173619 | E17: 16 | F17: 50490000 | G17: =IFERROR(D17/F17,0) -> 0.61742165 | H17: 3330000 | I17: =F17-H17 -> 47160000
A18: 15 | B18: 46218 | D18: ='NH Anh CT'!R17 -> 7745617.3 | E18: 16 | F18: 51525000 | G18: =IFERROR(D18/F18,0) -> 0.15032736 | H18: 11860000 | I18: =F18-H18 -> 39665000
A19: 16 | B19: 46219 | D19: ='NH Anh CT'!S17 -> 26358824 | E19: 8 | F19: 24970000 | G19: =IFERROR(D19/F19,0) -> 1.0556197 | I19: =F19-H19 -> 24970000
A20: 17 | B20: 46220 | D20: ='NH Anh CT'!T17 -> 21106822 | E20: 20 | F20: 65865000 | G20: =IFERROR(D20/F20,0) -> 0.32045581 | H20: 9775000 | I20: =F20-H20 -> 56090000
A21: 18 | B21: 46221 | D21: ='NH Anh CT'!U17 -> 26177273 | E21: 12 | F21: 39025000 | G21: =IFERROR(D21/F21,0) -> 0.67078213 | H21: 15780000 | I21: =F21-H21 -> 23245000
A22: 19 | B22: 46222 | D22: ='NH Anh CT'!V17 -> 35190144 | E22: 13 | F22: 42510000 | G22: =IFERROR(D22/F22,0) -> 0.8278086 | H22: 3375000 | I22: =F22-H22 -> 39135000
A23: 20 | B23: 46223 | D23: ='NH Anh CT'!W17 -> 10454013 | E23: 15 | F23: 41975000 | G23: =IFERROR(D23/F23,0) -> 0.24905331 | H23: 13360000 | I23: =F23-H23 -> 28615000
A24: 21 | B24: 46224 | D24: ='NH Anh CT'!X17 -> 35497105 | E24: 14 | F24: 44645000 | G24: =IFERROR(D24/F24,0) -> 0.79509698 | H24: 6730000 | I24: =F24-H24 -> 37915000
A25: 22 | B25: 46225 | D25: ='NH Anh CT'!Y17 -> 31560835 | E25: 17 | F25: 50365000 | G25: =IFERROR(D25/F25,0) -> 0.6266422 | H25: 3330000 | I25: =F25-H25 -> 47035000
A26: 23 | B26: 46226 | D26: ='NH Anh CT'!Z17 -> 18123156 | E26: 21 | F26: 68085000 | G26: =IFERROR(D26/F26,0) -> 0.26618428 | H26: 12950000 | I26: =F26-H26 -> 55135000
A27: 24 | B27: 46227 | D27: ='NH Anh CT'!AA17 -> 35071099 | E27: 13 | F27: 43030000 | G27: =IFERROR(D27/F27,0) -> 0.81503832 | I27: =F27-H27 -> 43030000
A28: 25 | B28: 46228 | D28: ='NH Anh CT'!AB17 -> 26859347 | E28: 13 | F28: 44250000 | G28: =IFERROR(D28/F28,0) -> 0.6069909 | H28: 18765000 | I28: =F28-H28 -> 25485000
A29: 26 | B29: 46229 | D29: ='NH Anh CT'!AC17 -> 18659398 | E29: 7 | F29: 22630000 | G29: =IFERROR(D29/F29,0) -> 0.82454256 | H29: 6955000 | I29: =F29-H29 -> 15675000
A30: 27 | B30: 46230 | D30: ='NH Anh CT'!AD17 -> 17169156 | E30: 12 | F30: 39690000 | G30: =IFERROR(D30/F30,0) -> 0.43258142 | H30: 13580000 | I30: =F30-H30 -> 26110000
A31: 28 | B31: 46231 | D31: ='NH Anh CT'!AE17 -> 0 | E31: 3 | F31: 9830000 | G31: =IFERROR(D31/F31,0) -> 0 | H31: 3545000 | I31: =F31-H31 -> 6285000
A32: 29 | B32: 46232 | D32: ='NH Anh CT'!AF17 -> 34213241 | E32: 8 | F32: 25900000 | G32: =IFERROR(D32/F32,0) -> 1.3209746 | I32: =F32-H32 -> 25900000
A33: 30 | B33: 46233 | D33: ='NH Anh CT'!AG17 -> 37684788 | E33: 23 | F33: 72730000 | G33: =IFERROR(D33/F33,0) -> 0.51814641 | H33: 19015000 | I33: =F33-H33 -> 53715000
A34: 31 | B34: 46234 | D34: ='NH Anh CT'!AH17 -> 26483158 | E34: 10 | F34: 32525000 | G34: =IFERROR(D34/F34,0) -> 0.81424007 | H34: 2910000 | I34: =F34-H34 -> 29615000
F35: -140480979

Sheet NH Anh CT
A2: STT | B2: Số tài khoản | C2: Số Thẻ | D2: Số tiền chi tiêu hàng ngày theo đầu thẻ
D3: 46204 | E3: 46205 | F3: 46206 | G3: 46207 | H3: 46208 | I3: 46209 | J3: 46210 | K3: 46211 | L3: 46212 | M3: 46213 | N3: 46214 | O3: 46215 | P3: 46216 | Q3: 46217 | R3: 46218 | S3: 46219 | T3: 46220 | U3: 46221 | V3: 46222 | W3: 46223 | X3: 46224 | Y3: 46225 | Z3: 46226 | AA3: 46227 | AB3: 46228 | AC3: 46229 | AD3: 46230 | AE3: 46231 | AF3: 46232 | AG3: 46233 | AH3: 46234
A4: 1 | B4: 7923 - 065 | C4: 7923 | D4: 5511690 | E4: 5613204 | F4: 7336395 | G4: 14795410 | H4: 1618843 | I4: 5384264 | J4: 12930578 | K4: 10244363 | L4: 2484540 | M4: 15731276 | N4: 9025924 | O4: 14703345 | P4: 14703345 | Q4: 14191580 | R4: 4156160 | S4: 12802073 | T4: 14191580 | U4: 14191580 | V4: 14191580 | W4: 11499414 | X4: 14191580 | Y4: 14191580 | Z4: 16185085 | AA4: 16185085 | AB4: 16185085 | AC4: 11499414 | AD4: 16185085 | AF4: 2024595 | AG4: 16185085 | AH4: 4766134
A5: 2 | D5: 5746165 | E5: 7990992 | F5: 7990992 | G5: 2733757 | H5: 12210187 | I5: 7776006 | J5: 9025924 | K5: 13921873 | L5: 10244363 | M5: 11504087 | N5: 4661418 | O5: 2098560 | P5: 9914329 | Q5: 9025924 | R5: 4364019 | S5: 14603420 | T5: 9025924 | U5: 14603420 | V5: 9025924 | X5: 9025924 | Y5: 9025924 | Z5: 3750387 | AA5: 9025924 | AB5: 11499414 | AC5: 9025924 | AD5: 2062871 | AF5: 4049190 | AG5: 1130397 | AH5: 250468
A6: 3 | D6: 14216873 | E6: 17764992 | G6: 12027381 | H6: 974840 | I6: 12262824 | J6: 5978921 | L6: 9025924 | N6: 10338551 | O6: 9914329 | Q6: 11073477 | S6: 1589213 | V6: 11499414 | X6: 4329897 | Y6: 11499414 | AA6: 11499414 | AB6: 1860783 | AD6: 638116 | AF6: 8098380 | AG6: 2260795 | AH6: 1753281
A7: 4 | D7: 12380291 | E7: 8888615 | H7: 1949680 | I7: 9025924 | J7: 7776006 | L7: 15731276 | V7: 3992240 | X7: 11499414 | AA7: 1867786 | AF7: 2024596 | AG7: 11499414 | AH7: 16241259
A8: 5 | D8: 9347458 | H8: 4255695 | AF8: 1162438 | AG8: 5310315 | AH8: 6120332
A9: 6 | D9: 6652074 | AF9: 2324876 | AG9: 663924
A10: 7 | D10: 15224 | AF10: 4649753 | AG10: 4403337
A11: 8 | AF11: 1162444
A12: 9 | AF12: 1517286
A13: 10 | AF13: 3034572
A14: 11 | AF14: 6069144
A15: 12 | AF15: 1517291
A16: 13
A17: Tổng | C17: =+D17+E17+F17+G17+H17+I17+J17+K17+L17+M17+N17+O17++P17+Q17+R17+S17+T17+U17+V17+W17+X17+Y17+Z17+AA17+AB17+AC17+AD17+AE17+AF17+AG17+AH17 -> 7.9809915e+08 | D17: =SUM(D4:D16) /1.1 -> 48972523 | E17: =SUM(E4:E16) /1.1 -> 36598003 | F17: =SUM(F4:F16) /1.1 -> 13933988 | G17: =SUM(G4:G16) /1.1 -> 26869589 | H17: =SUM(H4:H16) /1.1 -> 19099314 | I17: =SUM(I4:I16) /1.1 -> 31317289 | J17: =SUM(J4:J16) /1.1 -> 32464935 | K17: =SUM(K4:K16) /1.1 -> 21969305 | ... AH17: =SUM(AH4:AH16) /1.1 -> 26483158
A18: Kế toán check Hóa đơn
A19: Chênh lệch | D19: =D17-D18 -> 48972523 | E19: =E17-E18 -> 36598003 | F19: =F17-F18 -> 13933988 | G19: =G17-G18 -> 26869589 | H19: =H17-H18 -> 19099314 | I19: =I17-I18 -> 31317289 | J19: =J17-J18 -> 32464935 | K19: =K17-K18 -> 21969305 | ... AH19: =AH17-AH18 -> 26483158
B22: Facebook Billing
B23: Ngày thanh toán | C23: Phương thức TT | D23: Số tham chiếu thẻ | E23: Số tiền | G23: Link thư mục ảnh hóa đơn | I23: https://drive.google.com/drive/folders/1KxKUAAoEgDO60LcR79CJ55uehYCleDOu?usp=sharing | J23: Ten tab nguon | K23: Kiem tra so tien
B24: 46204 | C24: Visa ···· 7923 | D24: ACAGSV97J2 | E24: 6652074 | F24: 1 Tháng 7, 2026 | G24: 6652074 | H24: Visa ···· 7923 | I24: ACAGSV97J2 | J24: Trang tính13 | K24: Khớp
B25: 46204 | C25: Visa ···· 7923 | D25: HRZ34WZGX2 | E25: 5511690 | F25: 1 Tháng 7, 2026 | G25: 5511690 | H25: Visa ···· 7923 | I25: HRZ34WZGX2 | J25: Trang tính5 | K25: Khớp
B26: 46204 | C26: Visa ···· 7923 | D26: Q2UD6VVHX2 | E26: 5746165 | F26: 1 Tháng 7, 2026 | G26: 5746165 | H26: Visa ···· 7923 | I26: Q2UD6VVHX2 | J26: Trang tính5 | K26: Khớp
B27: 46205 | C27: Visa ···· 7923 | D27: YGZ2LV5HX2 | E27: 5613204 | F27: 2 Tháng 7, 2026 | G27: 5613204 | H27: Visa ···· 7923 | I27: YGZ2LV5HX2 | J27: Trang tính5 | K27: Khớp
B28: 46205 | C28: Visa ···· 7923 | D28: D8LPAVVHX2 | E28: 7990992 | F28: 2 Tháng 7, 2026 | G28: 7990992 | H28: Visa ···· 7923 | I28: D8LPAVVHX2 | J28: Trang tính5 | K28: Khớp
B29: 46206 | C29: Visa ···· 7923 | D29: 8PGASYRHX2 | E29: 7990992 | F29: 3 Tháng 7, 2026 | G29: 7990992 | H29: Visa ···· 7923 | I29: 8PGASYRHX2 | J29: Trang tính5 | K29: Khớp
B30: 46208 | C30: Visa ···· 7923 | D30: 3CHDWV5HX2 | E30: 12210187 | F30: 5 Tháng 7, 2026 | G30: 12210187 | H30: Visa ···· 7923 | I30: 3CHDWV5HX2 | J30: Trang tính5 | K30: Khớp
B31: 46208 | C31: Visa ···· 7923 | D31: 8ZMGZYRHX2 | E31: 974840 | F31: 5 Tháng 7, 2026 | G31: 974840 | H31: Visa ···· 7923 | I31: 8ZMGZYRHX2 | J31: Trang tính5 | K31: Khớp
B32: 46208 | C32: Visa ···· 7923 | D32: N8RR7WVGX2 | E32: 1949680 | F32: 5 Tháng 7, 2026 | G32: 1949680 | H32: Visa ···· 7923 | I32: N8RR7WVGX2 | J32: Trang tính5 | K32: Khớp
B33: 46209 | C33: Visa ···· 7923 | D33: BF5D5W9HX2 | E33: 5384264 | F33: 6 Tháng 7, 2026 | G33: 5384264 | H33: Visa ···· 7923 | I33: BF5D5W9HX2 | J33: Trang tính5 | K33: Khớp
B34: 46209 | C34: Visa ···· 7923 | D34: 83XVQVVHX2 | E34: 7776006 | F34: 6 Tháng 7, 2026 | G34: 7776006 | H34: Visa ···· 7923 | I34: 83XVQVVHX2 | J34: Trang tính5 | K34: Khớp
B35: 46210 | C35: Visa ···· 7923 | D35: 7C8P9W9HX2 | E35: 7776006 | F35: 7 Tháng 7, 2026 | G35: 7776006 | H35: Visa ···· 7923 | I35: 7C8P9W9HX2 | J35: Trang tính5 | K35: Khớp
... B59: 46234 | C59: Visa ···· 7923 | D59: TELCFYVHX2 | E59: 4766134 | F59: 31 Tháng 7, 2026 | G59: 4766134 | H59: Visa ···· 7923 | I59: TELCFYVHX2 | J59: Trang tính5 | K59: Khớp
B60: 46204 | C60: Visa ···· 7923 | D60: HMPTDVZ6U2 | E60: 14216873 | F60: 46204 | G60: 14216873 | H60: Visa ···· 7923 | I60: HMPTDVZ6U2 | J60: Hoàng Anh ADS 01 (6803316976993 | K60: Khớp
B61: 46204 | C61: Visa ···· 7923 | D61: 7ZTGYVH7U2 | E61: 12380291 | F61: 46204 | G61: 12380291 | H61: Visa ···· 7923 | I61: 7ZTGYVH7U2 | J61: Hoàng Anh ADS 01 (6803316976993 | K61: Khớp
B62: 46205 | C62: Visa ···· 7923 | D62: F6ZPEVV6U2 | E62: 17764992 | F62: 46205 | G62: 17764992 | H62: Visa ···· 7923 | I62: F6ZPEVV6U2 | J62: Hoàng Anh ADS 01 (6803316976993 | K62: Khớp
B63: 46206 | C63: Visa ···· 7923 | D63: VXEVUUD7U2 | E63: 7336395 | F63: 46206 | G63: 7336395 | H63: Visa ···· 7923 | I63: VXEVUUD7U2 | J63: Hoàng Anh ADS 01 (6803316976993 | K63: Khớp
B64: 46207 | C64: Visa ···· 7923 | D64: NBGJYWR6U2 | E64: 14795410 | F64: 46207 | G64: 14795410 | H64: Visa ···· 7923 | I64: NBGJYWR6U2 | J64: Hoàng Anh ADS 01 (6803316976993 | K64: Khớp
B65: 46207 | C65: Visa ···· 7923 | D65: DBFDHW97U2 | E65: 2733757 | F65: 46207 | G65: 2733757 | H65: Visa ···· 7923 | I65: DBFDHW97U2 | J65: Hoàng Anh ADS 01 (6803316976993 | K65: Khớp
B66: 46208 | C66: Visa ···· 7923 | D66: ANP3QVV6U2 | E66: 1618843 | F66: 46208 | G66: 1618843 | H66: Visa ···· 7923 | I66: ANP3QVV6U2 | J66: Hoàng Anh ADS 01 (6803316976993 | K66: Khớp
...

Sheet BQ Anh T
A2: STT | B2: Ngày/tháng | C2: Ngân sách cấp | D2: Tổng đã chi | E2: Số đơn | F2: Doanh số | G2: Tỷ lệ CP | H2: Hoàn - Hủy | I2: DS trước HH
C3: =+SUM(C4:C34) -> 113000000 | D3: =SUM(D4:D34) -> 2.7254576e+08 | E3: =SUM(E4:E34) -> 168 | F3: =SUM(F4:F36) -> 520556882 | G3: =IFERROR(D3/F3,0) -> 0.52356575
A4: 1 | B4: 46204 | C4: 24000000 | D4: ='BQ Anh CT'!D8 -> 14851365 | E4: 4 | F4: 11840000 | G4: =IFERROR(D4/F4,0) -> 1.2543383
A5: 2 | B5: 46205 | D5: ='BQ Anh CT'!E8 -> 12634924 | E5: 4 | F5: =I5-H5 -> 8665000 | G5: =IFERROR(D5/F5,0) -> 1.4581562 | H5: 3305000 | I5: 11970000
A6: 3 | B6: 46206 | C6: 36000000 | D6: ='BQ Anh CT'!F8 -> 16736405 | E6: 5 | F6: =I6-H6 -> 13075000 | G6: =IFERROR(D6/F6,0) -> 1.2800309 | H6: 3015000 | I6: 16090000
A7: 4 | B7: 46207 | C7: 5000000 | D7: ='BQ Anh CT'!G8 -> 15952055 | E7: 4 | F7: =I7-H7 -> 9080000 | G7: =IFERROR(D7/F7,0) -> 1.7568342 | H7: 9375000 | I7: 18455000
A8: 5 | B8: 46208 | D8: ='BQ Anh CT'!H8 -> 4189222.7 | E8: 3 | F8: =I8-H8 -> 0 | G8: =IFERROR(D8/F8,0) -> 0 | H8: 8955000 | I8: 8955000
A9: 6 | B9: 46209 | C9: 48000000 | D9: ='BQ Anh CT'!I8 -> 10286163 | E9: 7 | F9: =I9-H9 -> 19275000 | G9: =IFERROR(D9/F9,0) -> 0.53365306 | H9: 2355000 | I9: 21630000
A10: 7 | B10: 46210 | D10: ='BQ Anh CT'!J8 -> 9216375.5 | E10: 10 | F10: =I10-H10 -> 25890000 | G10: =IFERROR(D10/F10,0) -> 0.35598206 | H10: 3375000 | I10: 29265000
A11: 8 | B11: 46211 | D11: ='BQ Anh CT'!K8 -> 13312893 | E11: 11 | F11: =I11-H11 -> 29365000 | G11: =IFERROR(D11/F11,0) -> 0.45335919 | H11: 6740000 | I11: 36105000
A12: 9 | B12: 46212 | D12: ='BQ Anh CT'!L8 -> 7668873.6 | E12: 8 | F12: =I12-H12 -> 25610000 | G12: =IFERROR(D12/F12,0) -> 0.2994484 | H12: 0 | I12: 25610000
A13: 10 | B13: 46213 | D13: ='BQ Anh CT'!M8 -> 12260316 | E13: 5 | F13: =I13-H13 -> 11545000 | G13: =IFERROR(D13/F13,0) -> 1.061959 | H13: 2910000 | I13: 14455000
A14: 11 | B14: 46214 | D14: ='BQ Anh CT'!N8 -> 3033847.3 | E14: 6 | F14: 21170000 | G14: =IFERROR(D14/F14,0) -> 0.1433088 | H14: 0 | I14: 21170000
A15: 12 | B15: 46215 | D15: ='BQ Anh CT'!O8 -> 15948178 | E15: 2 | F15: 5920000 | G15: =IFERROR(D15/F15,0) -> 2.693949 | H15: 0 | I15: 5920000
A16: 13 | B16: 46216 | D16: ='BQ Anh CT'!P8 -> 0 | E16: 5 | F16: =I16-H16 -> 11430000 | G16: =IFERROR(D16/F16,0) -> 0 | H16: 2910000 | I16: 14340000
A17: 14 | B17: 46217 | D17: ='BQ Anh CT'!Q8 -> 8809666.4 | E17: 5 | F17: 15280000 | G17: =IFERROR(D17/F17,0) -> 0.57654885 | H17: 0 | I17: 15280000
A18: 15 | B18: 46218 | D18: ='BQ Anh CT'!R8 -> 17293848 | E18: 4 | F18: =I18-H18 -> 2910000 | G18: =IFERROR(D18/F18,0) -> 5.9429032 | H18: 9780000 | I18: 12690000
A19: 16 | B19: 46219 | D19: ='BQ Anh CT'!S8 -> 6047613.6 | E19: 3 | F19: =I19-H19 -> 5245000 | G19: =IFERROR(D19/F19,0) -> 1.1530245 | H19: 4030000 | I19: 9275000
A20: 17 | B20: 46220 | D20: ='BQ Anh CT'!T8 -> 8467755.5 | E20: 5 | F20: =I20-H20 -> 6780000 | G20: =IFERROR(D20/F20,0) -> 1.2489315 | H20: 9775000 | I20: 16555000
A21: 18 | B21: 46221 | D21: ='BQ Anh CT'!U8 -> 9121957.3 | E21: 6 | F21: =I21-H21 -> 13420000 | G21: =IFERROR(D21/F21,0) -> 0.67972856 | H21: 6730000 | I21: 20150000
A22: 19 | B22: 46222 | D22: ='BQ Anh CT'!V8 -> 7268960 | E22: 4 | F22: 13815000 | G22: =IFERROR(D22/F22,0) -> 0.52616431 | H22: 0 | I22: 13815000
A23: 20 | B23: 46223 | D23: ='BQ Anh CT'!W8 -> 8375782.7 | E23: 9 | F23: 29905000 | G23: =IFERROR(D23/F23,0) -> 0.28007968 | H23: 0 | I23: 29905000
A24: 21 | B24: 46224 | D24: ='BQ Anh CT'!X8 -> 7268960 | E24: 3 | F24: 9840000 | G24: =IFERROR(D24/F24,0) -> 0.73871545
A25: 22 | B25: 46225 | D25: ='BQ Anh CT'!Y8 -> 0 | E25: 12 | F25: =I25-H25 -> 35810000 | G25: =IFERROR(D25/F25,0) -> 0 | H25: 3015000 | I25: 38825000
A26: 23 | B26: 46226 | D26: ='BQ Anh CT'!Z8 -> 18322650 | E26: 4 | F26: 13200000 | G26: =IFERROR(D26/F26,0) -> 1.3880795
A27: 24 | B27: 46227 | D27: ='BQ Anh CT'!AA8 -> 0 | E27: 5 | F27: 16230000 | G27: =IFERROR(D27/F27,0) -> 0
A28: 25 | B28: 46228 | D28: ='BQ Anh CT'!AB8 -> 0 | E28: 5 | F28: =I28-H28 -> 10475000 | G28: =IFERROR(D28/F28,0) -> 0 | H28: 5900000 | I28: 16375000
A29: 26 | B29: 46229 | D29: ='BQ Anh CT'!AC8 -> 24551004 | E29: 7 | F29: 22085000 | G29: =IFERROR(D29/F29,0) -> 1.1116597
A30: 27 | B30: 46230 | D30: ='BQ Anh CT'!AD8 -> 6589455.5 | E30: 4 | F30: 15455000 | G30: =IFERROR(D30/F30,0) -> 0.42636399
A31: 28 | B31: 46231 | D31: ='BQ Anh CT'!AE8 -> 14337485 | E31: 3 | F31: 10425000 | G31: =IFERROR(D31/F31,0) -> 1.3752984
A32: 29 | B32: 46232 | D32: ='BQ Anh CT'!AF8 -> 0 | E32: 8 | F32: 25685000 | G32: =IFERROR(D32/F32,0) -> 0
A33: 30 | B33: 46233 | D33: ='BQ Anh CT'!AG8 -> 0 | E33: 4 | F33: 12680000 | G33: =IFERROR(D33/F33,0) -> 0
A34: 31 | B34: 46234 | D34: ='BQ Anh CT'!AH8 -> 0 | E34: 3 | F34: 10839696 | G34: =IFERROR(D34/F34,0) -> 0
B35: Hotline | F35: 57612186

Sheet BQ Anh CT
A2: STT | B2: Số tài khoản | C2: Số Thẻ | D2: Số tiền chi tiêu hàng ngày theo đầu thẻ
D3: 46204 | E3: 46205 | F3: 46206 | G3: 46207 | H3: 46208 | I3: 46209 | J3: 46210 | K3: 46211 | L3: 46212 | M3: 46213 | N3: 46214 | O3: 46215 | P3: 46216 | Q3: 46217 | R3: 46218 | S3: 46219 | T3: 46220 | U3: 46221 | V3: 46222 | W3: 46223 | X3: 46224 | Y3: 46225 | Z3: 46226 | AA3: 46227 | AB3: 46228 | AC3: 46229 | AD3: 46230 | AE3: 46231 | AF3: 46232 | AG3: 46233 | AH3: 46234
A4: 1 | B4: 9793 - 801 | C4: 9793 | D4: 9229260 | E4: 5182161 | F4: 8289036 | G4: 8289036 | H4: 0 | I4: 8289036 | J4: 0 | K4: 7805956 | L4: 3521304 | M4: 6123162 | N4: 0 | O4: 9383041 | P4: 0 | Q4: 9690633 | R4: 9690633 | S4: 0 | T4: 0 | U4: 10034153 | V4: 0 | W4: 9213361 | X4: 0 | Y4: 0 | Z4: 8984129 | AA4: 0 | AC4: 12456320 | AD4: 0 | AE4: 8522833
A5: 2 | D5: 5032621 | E5: 2720540 | F5: 7120282 | G5: 6257497 | H5: 1327332 | J5: 7120282 | K5: 6838226 | L5: 0 | M5: 7363186 | N5: 0 | O5: 8159955 | P5: 0 | Q5: 0 | R5: 9332600 | S5: 0 | T5: 9314531 | U5: 0 | V5: 7995856 | W5: 0 | X5: 7995856 | Z5: 11170786 | AA5: 0 | AB5: 0 | AC5: 14549784 | AD5: 7248401 | AE5: 7248401
A6: 3 | D6: 2074621 | E6: 4061484 | F6: 3000727 | G6: 3000727 | H6: 3280813 | I6: 3025743 | J6: 3017731 | K6: 0 | L6: 4914457 | M6: 0 | N6: 3337232 | O6: 0 | P6: 0 | Q6: 0 | R6: 0 | S6: 6652375 | T6: 0 | U6: 0 | V6: 0 | W6: 0 | X6: 0 | Y6: 0 | AA6: 0 | AB6: 0 | AC6: 0 | AD6: 0
A7: 4 | E7: 1934231
A8: Tổng | C8: =+D8+E8+F8+G8+H8+I8+J8+K8+L8+M8+N8+O8++P8+Q8+R8+S8+T8+U8+V8+W8+X8+Y8+Z8+AA8+AB8+AC8+AD8+AE8+AF8+AG8+AH8 -> 2.7254576e+08 | D8: =SUM(D4:D7) /1.1 -> 14851365 | E8: =SUM(E4:E7) /1.1 -> 12634924 | F8: =SUM(F4:F7) /1.1 -> 16736405 | G8: =SUM(G4:G7) /1.1 -> 15952055 | H8: =SUM(H4:H7) /1.1 -> 4189222.7 | I8: =SUM(I4:I7) /1.1 -> 10286163 | J8: =SUM(J4:J7) /1.1 -> 9216375.5 | K8: =SUM(K4:K7) /1.1 -> 13312893 | ... AH8: =SUM(AH4:AH7) /1.1 -> 0
A9: Kế toán check Hóa đơn
A10: Chênh lệch | D10: =D8-D9 -> 14851365 | E10: =E8-E9 -> 12634924 | F10: =F8-F9 -> 16736405 | G10: =G8-G9 -> 15952055 | H10: =H8-H9 -> 4189222.7 | I10: =I8-I9 -> 10286163 | J10: =J8-J9 -> 9216375.5 | K10: =K8-K9 -> 13312893 | ... AH10: =AH8-AH9 -> 0
B14: Facebook Billing
B15: Ngày thanh toán | C15: Phương thức TT | D15: Số tham chiếu thẻ | E15: Số tiền | G15: Link thư mục ảnh hóa đơn | I15: Hóa Đơn Tháng 7 | J15: Ten tab nguon | K15: Kiem tra so tien
B16: 46204 | C16: Visa ···· 9793 | D16: TQWMGV5HX2 | E16: 9229260 | F16: 1 Tháng 7, 2026 | G16: 9229260 | H16: Visa ···· 9793 | I16: TQWMGV5HX2 | J16: Trang tính12 | K16: Khớp
B17: 46204 | C17: Visa ···· 9793 | D17: 9YWUKV9HX2 | E17: 5032621 | F17: 1 Tháng 7, 2026 | G17: 5032621 | H17: Visa ···· 9793 | I17: 9YWUKV9HX2 | J17: Trang tính8 | K17: Khớp
B18: 46204 | C18: Visa ···· 9793 | D18: CM3HYVVJK2 | E18: 2074621 | F18: 1 Tháng 7, 2026 | G18: 2074621 | H18: Visa ···· 9793 | I18: CM3HYVVJK2 | J18: Quang Anh 1 +7 (861578506991731 | K18: Khớp
B19: 46205 | C19: Visa ···· 9793 | D19: CNFBXUMHX2 | E19: 5182161 | F19: 2 Tháng 7, 2026 | G19: 5182161 | H19: Visa ···· 9793 | I19: CNFBXUMHX2 | J19: Trang tính12 | K19: Khớp
B20: 46205 | C20: Visa ···· 9793 | D20: P242LV5HX2 | E20: 2720540 | F20: 2 Tháng 7, 2026 | G20: 2720540 | H20: Visa ···· 9793 | I20: P242LV5HX2 | J20: Trang tính8 | K20: Khớp
B21: 46205 | C21: Visa ···· 9793 | D21: A7FBYUMHX2 | E21: 1934231 | F21: 2 Tháng 7, 2026 | G21: 1934231 | H21: Visa ···· 9793 | I21: A7FBYUMHX2 | J21: Trang tính14 | K21: Khớp
B22: 46205 | C22: Visa ···· 9793 | D22: XJCLBUZJK2 | E22: 2030742 | F22: 2 Tháng 7, 2026 | G22: 2030742 | H22: Visa ···· 9793 | I22: XJCLBUZJK2 | J22: Quang Anh 1 +7 (861578506991731 | K22: Khớp
B23: 46205 | C23: Visa ···· 9793 | D23: GGZP3WDJK2 | E23: 2030742 | F23: 2 Tháng 7, 2026 | G23: 2030742 | H23: Visa ···· 9793 | I23: GGZP3WDJK2 | J23: Quang Anh 1 +7 (861578506991731 | K23: Khớp
B24: 46206 | C24: Visa ···· 9793 | D24: DNH6XVDHX2 | E24: 8289036 | F24: 3 Tháng 7, 2026 | G24: 8289036 | H24: Visa ···· 9793 | I24: DNH6XVDHX2 | J24: Trang tính12 | K24: Khớp
B25: 46206 | C25: Visa ···· 9793 | D25: ZAAXCVVHX2 | E25: 7120282 | F25: 3 Tháng 7, 2026 | G25: 7120282 | H25: Visa ···· 9793 | I25: ZAAXCVVHX2 | J25: Trang tính8 | K25: Khớp
B26: 46206 | C26: Visa ···· 9793 | D26: 3QUFBURJK2 | E26: 3000727 | F26: 3 Tháng 7, 2026 | G26: 3000727 | H26: Visa ···· 9793 | I26: 3QUFBURJK2 | J26: Quang Anh 1 +7 (861578506991731 | K26: Khớp
B27: 46207 | C27: Visa ···· 9793 | D27: WSB23WDHX2 | E27: 8289036 | F27: 4 Tháng 7, 2026 | G27: 8289036 | H27: Visa ···· 9793 | I27: WSB23WDHX2 | J27: Trang tính12 | K27: Khớp
... B66: 46231 | C66: Visa ···· 9793 | D66: XLQUNYDHX2 | E66: 7248401 | F66: 28 Tháng 7, 2026 | G66: 7248401 | H66: Visa ···· 9793 | I66: XLQUNYDHX2 | J66: Trang tính8 | K66: Khớp
B67: Tổng Bill Tháng 7 (Chưa - 10% VAT) | E67: =SUM(E15:E66) -> 299800991

Sheet TQ Huy T
A2: STT | B2: Ngày/tháng | C2: Ngân sách cấp | D2: Tổng đã chi | E2: Số đơn | F2: Doanh số | G2: Tỷ lệ CP
C3: =+SUM(C4:C34) -> 246000000 | D3: =SUM(D4:D34) -> 3.1075743e+08 | E3: =SUM(E4:E34) -> 101 | F3: =SUM(F4:F36) -> 408820000 | G3: =IFERROR(D3/F3,0) -> 0.76013265
A4: 1 | B4: 46204 | C4: 15000000 | D4: ='TQ Huy CT'!D9 -> 6657850 | E4: 7 | F4: 21765000 | G4: =IFERROR(D4/F4,0) -> 0.30589708
A5: 2 | B5: 46205 | C5: 15000000 | D5: ='TQ Huy CT'!E9 -> 2588287.3 | E5: 4 | F5: 12240000 | G5: =IFERROR(D5/F5,0) -> 0.21146138
A6: 3 | B6: 46206 | C6: 15000000 | D6: ='TQ Huy CT'!F9 -> 22239335 | E6: 6 | F6: 18740000 | G6: =IFERROR(D6/F6,0) -> 1.1867308
A7: 4 | B7: 46207 | C7: 15000000 | D7: ='TQ Huy CT'!G9 -> 7068731.8 | E7: 2 | F7: 6660000 | G7: =IFERROR(D7/F7,0) -> 1.0613711
A8: 5 | B8: 46208 | C8: 15000000 | D8: ='TQ Huy CT'!H9 -> 16341012 | E8: 3 | F8: 9940000 | G8: =IFERROR(D8/F8,0) -> 1.643965
A9: 6 | B9: 46209 | C9: 15000000 | D9: ='TQ Huy CT'!I9 -> 17305372 | E9: 3 | F9: 8730000 | G9: =IFERROR(D9/F9,0) -> 1.9822877
A10: 7 | B10: 46210 | C10: 15000000 | D10: ='TQ Huy CT'!J9 -> 9099639.1 | E10: 5 | F10: 15875000 | G10: =IFERROR(D10/F10,0) -> 0.57320561
A11: 8 | B11: 46211 | C11: 15000000 | D11: ='TQ Huy CT'!K9 -> 13423787 | E11: 6 | F11: 19315000 | G11: =IFERROR(D11/F11,0) -> 0.69499287
A12: 9 | B12: 46212 | C12: 15000000 | D12: ='TQ Huy CT'!L9 -> 3670010 | E12: 1 | F12: 3850000 | G12: =IFERROR(D12/F12,0) -> 0.95324935
A13: 10 | B13: 46213 | C13: 15000000 | D13: ='TQ Huy CT'!M9 -> 7690731.8 | E13: 4 | F13: 13110000 | G13: =IFERROR(D13/F13,0) -> 0.58663095
A14: 11 | B14: 46214 | C14: 15000000 | D14: ='TQ Huy CT'!N9 -> 11316056 | E14: 3 | F14: 9255000 | G14: =IFERROR(D14/F14,0) -> 1.2226965
A15: 12 | B15: 46215 | C15: 15000000 | D15: ='TQ Huy CT'!O9 -> 4465834.5 | E15: 2 | F15: 7030000 | G15: =IFERROR(D15/F15,0) -> 0.63525385
A16: 13 | B16: 46216 | C16: 15000000 | D16: ='TQ Huy CT'!P9 -> 16295151 | E16: 5 | F16: 16515000 | G16: =IFERROR(D16/F16,0) -> 0.98668791
A17: 14 | B17: 46217 | C17: 15000000 | D17: ='TQ Huy CT'!Q9 -> 3836414.5 | E17: 5 | F17: 15585000 | G17: =IFERROR(D17/F17,0) -> 0.2461607
A18: 15 | B18: 46218 | C18: 12000000 | D18: ='TQ Huy CT'!R9 -> 9917607.3 | E18: 0 | F18: 0 | G18: =IFERROR(D18/F18,0) -> 0
A19: 16 | B19: 46219 | C19: 12000000 | D19: ='TQ Huy CT'!S9 -> 11458157 | E19: 4 | F19: 10995000 | G19: =IFERROR(D19/F19,0) -> 1.0421244
A20: 17 | B20: 46220 | C20: 12000000 | D20: ='TQ Huy CT'!T9 -> 6598888.2 | E20: 4 | F20: 14795000 | G20: =IFERROR(D20/F20,0) -> 0.44602151
A21: 18 | B21: 46221 | D21: ='TQ Huy CT'!U9 -> 6078433.6 | E21: 1 | F21: 3015000 | G21: =IFERROR(D21/F21,0) -> 2.0160642
A22: 19 | B22: 46222 | D22: ='TQ Huy CT'!V9 -> 14713877 | E22: 7 | F22: 24730000 | G22: =IFERROR(D22/F22,0) -> 0.59498088
A23: 20 | B23: 46223 | D23: ='TQ Huy CT'!W9 -> 6957442.7 | E23: 5 | F23: 19260000 | G23: =IFERROR(D23/F23,0) -> 0.36123794
A24: 21 | B24: 46224 | D24: ='TQ Huy CT'!X9 -> 7752108.2 | E24: 3 | F24: 8710000 | G24: =IFERROR(D24/F24,0) -> 0.8900239
A25: 22 | B25: 46225 | D25: ='TQ Huy CT'!Y9 -> 8760480 | E25: 7 | F25: 21760000 | G25: =IFERROR(D25/F25,0) -> 0.40259559
A26: 23 | B26: 46226 | D26: ='TQ Huy CT'!Z9 -> 6473571.8 | E26: 5 | F26: 17325000 | G26: =IFERROR(D26/F26,0) -> 0.37365494
A27: 24 | B27: 46227 | D27: ='TQ Huy CT'!AA9 -> 10074405 | E27: 2 | F27: 6240000 | G27: =IFERROR(D27/F27,0) -> 1.6144881
A28: 25 | B28: 46228 | D28: ='TQ Huy CT'!AB9 -> 6473571.8 | E28: 4 | F28: 14180000 | G28: =IFERROR(D28/F28,0) -> 0.45652834
A29: 26 | B29: 46229 | D29: ='TQ Huy CT'!AC9 -> 12450851 | E29: 3 | F29: 8970000 | G29: =IFERROR(D29/F29,0) -> 1.3880547
A30: 27 | B30: 46230 | D30: ='TQ Huy CT'!AD9 -> 13782515 | F30: 16035000 | G30: =IFERROR(D30/F30,0) -> 0.85952694
A31: 28 | B31: 46231 | D31: ='TQ Huy CT'!AE9 -> 2360441.8 | F31: 5705000 | G31: =IFERROR(D31/F31,0) -> 0.41374966
A32: 29 | B32: 46232 | D32: ='TQ Huy CT'!AF9 -> 0 | F32: 32015000 | G32: =IFERROR(D32/F32,0) -> 0
A33: 30 | B33: 46233 | D33: ='TQ Huy CT'!AG9 -> 24979795 | F33: 14350000 | G33: =IFERROR(D33/F33,0) -> 1.7407522
A34: 31 | B34: 46234 | D34: ='TQ Huy CT'!AH9 -> 19927070 | F34: 12125000 | G34: =IFERROR(D34/F34,0) -> 1.6434697

Sheet TQ Huy  CT
A2: STT | B2: Số tài khoản | C2: Số Thẻ | D2: Số tiền chi tiêu hàng ngày theo đầu thẻ
D3: 46204 | E3: 46205 | F3: 46206 | G3: 46207 | H3: 46208 | I3: 46209 | J3: 46210 | K3: 46211 | L3: 46212 | M3: 46213 | N3: 46214 | O3: 46215 | P3: 46216 | Q3: 46217 | R3: 46218 | S3: 46219 | T3: 46220 | U3: 46221 | V3: 46222 | W3: 46223 | X3: 46224 | Y3: 46225 | Z3: 46226 | AA3: 46227 | AB3: 46228 | AC3: 46229 | AD3: 46230 | AE3: 46231 | AF3: 46232 | AG3: 46233 | AH3: 46234
